Workbook

Sheet 기준
A1: 고양이 오메가3 제품 채점 기준 (v1 · 공개정보 기반 · 실측 전)
A2: 가중치: 성분 35 / 산패 30 / 원료·형태 20 / 투명성 15 | 안전 점수상한: 비해양성=ALA단독→20, 대구간유(肝油)→40, 산패고위험→50 | ※조류(algae) 오일은 EPA/DHA를 직접 공급=정상 처리 / 폴락 어체유는 간유 아님
B3: 비율표기
B4: 명시 | C4: 5
B5: 일부 | C5: 2
B6: 미표기 | C6: 0
B7: 미상 | C7: 0
B9: 형태
B10: rTG | C10: 10
B11: TG | C11: 10
B12: EE | C12: 5
B13: 미상 | C13: 5
B15: 어종
B16: 소형어 | C16: 10
B17: 일반어 | C17: 6
B18: 식물성 | C18: 0
B19: 조류 | C19: 8
B20: 미상 | C20: 3
B21: 항산화제
B22: 있음 | C22: 10
B23: 없음 | C23: 0
B24: 미상 | C24: 0
B26: 포장
B27: 우수 | C27: 10
B28: 보통 | C28: 5
B29: 취약 | C29: 0
B30: 미상 | C30: 0
B32: 제형
B33: 캡슐 | C33: 10
B34: 소프트젤 | C34: 10
B35: 츄 | C35: 6
B36: 스틱 | C36: 6
B37: 펌프액상 | C37: 6
B38: 대용량액상 | C38: 2
B39: 미상 | C39: 0
B41: 인증
B42: 있음 | C42: 5
B43: 없음 | C43: 0
B44: 미상 | C44: 0
B46: COA
...

Sheet 점수표
A1: 번호 | B1: 제품명 | C1: 분류 | D1: 밀도(EPA+DHA mg/단위) | E1: 순도(%) | F1: 비율표기 | G1: 형태 | H1: 어종 | I1: 항산화제 | J1: 포장 | K1: 제형 | L1: 인증 | M1: COA | N1: 원료사 | O1: 비해양성 | P1: 대구 | Q1: 산패고위험 | R1: 성분/35 | S1: 산패/30 | T1: 원료형태/20 | U1: 투명성/15 | V1: 합계 | W1: 안전상한 | X1: 최종점수 | Y1: 잠정순위 | Z1: 정보검증 | AA1: 적합성 | AB1: 데이터충실도 | AC1: 출처·비고
A2: 1 | B2: 닥터레이 오메가3 | C2: 펫·캡슐 | D2: 200 | E2: 80 | F2: 명시 | G2: rTG | H2: 소형어 | I2: 있음 | J2: 우수 | K2: 캡슐 | L2: 있음 | M2: 공개 | N2: 명시 | O2: N | P2: N | Q2: N | R2: =IF(NOT(ISNUMBER(D2)),0,IF(D2>=300,20,IF(D2>=200,15,IF(D2>=100,10,5))))+IF(NOT(ISNUMBER(E2)),0,IF(E2>=60,10,IF(E2>=40,6,3)))+IFERROR(VLOOKUP(F2,기준!$B$4:$C$7,2,FALSE()),0) -> 30 | S2: =IFERROR(VLOOKUP(I2,기준!$B$22:$C$24,2,FALSE()),0)+IFERROR(VLOOKUP(J2,기준!$B$27:$C$30,2,FALSE()),0)+IFERROR(VLOOKUP(K2,기준!$B$33:$C$39,2,FALSE()),0) -> 30 | T2: =IFERROR(VLOOKUP(G2,기준!$B$10:$C$13,2,FALSE()),0)+IFERROR(VLOOKUP(H2,기준!$B$16:$C$20,2,FALSE()),0) -> 20 | U2: =IFERROR(VLOOKUP(L2,기준!$B$42:$C$44,2,FALSE()),0)+IFERROR(VLOOKUP(M2,기준!$B$47:$C$50,2,FALSE()),0)+IFERROR(VLOOKUP(N2,기준!$B$53:$C$56,2,FALSE()),0) -> 15 | V2: =SUM(R2:U2) -> 95 | W2: =MIN(IF(O2="Y",20,100),IF(P2="Y",40,100),IF(Q2="Y",50,100)) -> 100 | X2: =MIN(V2,W2) -> 95 | Y2: =RANK(X2,$X$2:$X$34,0) -> 2 | Z2: 공개·검증 | AA2: 관절·신장(EPA우세) | AB2: =(IF(ISNUMBER(D2),1,0)+IF(ISNUMBER(E2),1,0)+IF(F2<>"미상",1,0)+IF(G2<>"미상",1,0)+IF(H2<>"미상",1,0)+IF(I2<>"미상",1,0)+IF(J2<>"미상",1,0)+IF(K2<>"미상",1,0)+IF(L2<>"미상",1,0)+IF(M2<>"미상",1,0)+IF(N2<>"미상",1,0))&"/11" -> 11/11 | AC2: 1캡슐 EPA120+DHA80=200mg·순도80%·rTG·멸치/정어리·d-토코페롤·PVDC블리스터·IFOS5★완제품(TOTOX10.32·산가0.17·중금속통과)·KD파마/로빈슨파마 (상세페이지 실측)
A3: 2 | B3: 조공 rTG 퓨어 오메가3 | C3: 펫·캡슐 | E3: 80 | F3: 미상 | G3: rTG | H3: 미상 | I3: 미상 | J3: 미상 | K3: 캡슐 | L3: 있음 | M3: 일부 | N3: 명시 | O3: N | P3: N | Q3: N | R3: =IF(NOT(ISNUMBER(D3)),0,IF(D3>=300,20,IF(D3>=200,15,IF(D3>=100,10,5))))+IF(NOT(ISNUMBER(E3)),0,IF(E3>=60,10,IF(E3>=40,6,3)))+IFERROR(VLOOKUP(F3,기준!$B$4:$C$7,2,FALSE()),0) -> 10 | S3: =IFERROR(VLOOKUP(I3,기준!$B$22:$C$24,2,FALSE()),0)+IFERROR(VLOOKUP(J3,기준!$B$27:$C$30,2,FALSE()),0)+IFERROR(VLOOKUP(K3,기준!$B$33:$C$39,2,FALSE()),0) -> 10 | T3: =IFERROR(VLOOKUP(G3,기준!$B$10:$C$13,2,FALSE()),0)+IFERROR(VLOOKUP(H3,기준!$B$16:$C$20,2,FALSE()),0) -> 13 | U3: =IFERROR(VLOOKUP(L3,기준!$B$42:$C$44,2,FALSE()),0)+IFERROR(VLOOKUP(M3,기준!$B$47:$C$50,2,FALSE()),0)+IFERROR(VLOOKUP(N3,기준!$B$53:$C$56,2,FALSE()),0) -> 12 | V3: =SUM(R3:U3) -> 45 | W3: =MIN(IF(O3="Y",20,100),IF(P3="Y",40,100),IF(Q3="Y",50,100)) -> 100 | X3: =MIN(V3,W3) -> 45 | Y3: =RANK(X3,$X$2:$X$34,0) -> 10 | Z3: 공개·검증 | AA3: 미정 | AB3: =(IF(ISNUMBER(D3),1,0)+IF(ISNUMBER(E3),1,0)+IF(F3<>"미상",1,0)+IF(G3<>"미상",1,0)+IF(H3<>"미상",1,0)+IF(I3<>"미상",1,0)+IF(J3<>"미상",1,0)+IF(K3<>"미상",1,0)+IF(L3<>"미상",1,0)+IF(M3<>"미상",1,0)+IF(N3<>"미상",1,0))&"/11" -> 6/11 | AC3: IFOS 5-star·Solutex·순도80%+ (모굿인)
A4: 3 | B4: 조공 레드 오메가3 미니 | C4: 펫·캡슐 | D4: 110 | E4: 80 | F4: 명시 | G4: rTG | H4: 소형어 | I4: 있음 | J4: 우수 | K4: 캡슐 | L4: 있음 | M4: 공개 | N4: 명시 | O4: N | P4: N | Q4: N | R4: =IF(NOT(ISNUMBER(D4)),0,IF(D4>=300,20,IF(D4>=200,15,IF(D4>=100,10,5))))+IF(NOT(ISNUMBER(E4)),0,IF(E4>=60,10,IF(E4>=40,6,3)))+IFERROR(VLOOKUP(F4,기준!$B$4:$C$7,2,FALSE()),0) -> 25 | S4: =IFERROR(VLOOKUP(I4,기준!$B$22:$C$24,2,FALSE()),0)+IFERROR(VLOOKUP(J4,기준!$B$27:$C$30,2,FALSE()),0)+IFERROR(VLOOKUP(K4,기준!$B$33:$C$39,2,FALSE()),0) -> 30 | T4: =IFERROR(VLOOKUP(G4,기준!$B$10:$C$13,2,FALSE()),0)+IFERROR(VLOOKUP(H4,기준!$B$16:$C$20,2,FALSE()),0) -> 20 | U4: =IFERROR(VLOOKUP(L4,기준!$B$42:$C$44,2,FALSE()),0)+IFERROR(VLOOKUP(M4,기준!$B$47:$C$50,2,FALSE()),0)+IFERROR(VLOOKUP(N4,기준!$B$53:$C$56,2,FALSE()),0) -> 15 | V4: =SUM(R4:U4) -> 90 | W4: =MIN(IF(O4="Y",20,100),IF(P4="Y",40,100),IF(Q4="Y",50,100)) -> 100 | X4: =MIN(V4,W4) -> 90 | Y4: =RANK(X4,$X$2:$X$34,0) -> 3 | Z4: 공개·검증 | AA4: 일반유지·피부(아스타잔틴) | AB4: =(IF(ISNUMBER(D4),1,0)+IF(ISNUMBER(E4),1,0)+IF(F4<>"미상",1,0)+IF(G4<>"미상",1,0)+IF(H4<>"미상",1,0)+IF(I4<>"미상",1,0)+IF(J4<>"미상",1,0)+IF(K4<>"미상",1,0)+IF(L4<>"미상",1,0)+IF(M4<>"미상",1,0)+IF(N4<>"미상",1,0))&"/11" -> 11/11 | AC4: 1캡슐 EPA66+DHA44=110mg(rTG오일137.6mg·순도80%)·멸치류 소형어·아스타잔틴5mg+d-토코페롤·블리스터개별포장·원료+완제품IFOS5★(TOTOX16.49·산가0.27·중금속통과)·Solutex/Viva제조·고양이1알 (상세페이지 실측)
A5: 4 | B5: 조공 데일리 퓨어 오메가-3 미니 | C5: 펫·캡슐 | D5: 110 | E5: 75 | F5: 명시 | G5: rTG | H5: 소형어 | I5: 있음 | J5: 보통 | K5: 캡슐 | L5: 있음 | M5: 공개 | N5: 명시 | O5: N | P5: N | Q5: N | R5: =IF(NOT(ISNUMBER(D5)),0,IF(D5>=300,20,IF(D5>=200,15,IF(D5>=100,10,5))))+IF(NOT(ISNUMBER(E5)),0,IF(E5>=60,10,IF(E5>=40,6,3)))+IFERROR(VLOOKUP(F5,기준!$B$4:$C$7,2,FALSE()),0) -> 25 | S5: =IFERROR(VLOOKUP(I5,기준!$B$22:$C$24,2,FALSE()),0)+IFERROR(VLOOKUP(J5,기준!$B$27:$C$30,2,FALSE()),0)+IFERROR(VLOOKUP(K5,기준!$B$33:$C$39,2,FALSE()),0) -> 25 | T5: =IFERROR(VLOOKUP(G5,기준!$B$10:$C$13,2,FALSE()),0)+IFERROR(VLOOKUP(H5,기준!$B$16:$C$20,2,FALSE()),0) -> 20 | U5: =IFERROR(VLOOKUP(L5,기준!$B$42:$C$44,2,FALSE()),0)+IFERROR(VLOOKUP(M5,기준!$B$47:$C$50,2,FALSE()),0)+IFERROR(VLOOKUP(N5,기준!$B$53:$C$56,2,FALSE()),0) -> 15 | V5: =SUM(R5:U5) -> 85 | W5: =MIN(IF(O5="Y",20,100),IF(P5="Y",40,100),IF(Q5="Y",50,100)) -> 100 | X5: =MIN(V5,W5) -> 85 | Y5: =RANK(X5,$X$2:$X$34,0) -> 4 | Z5: 공개·검증 | AA5: 일반유지(EPA 2:1) | AB5: =(IF(ISNUMBER(D5),1,0)+IF(ISNUMBER(E5),1,0)+IF(F5<>"미상",1,0)+IF(G5<>"미상",1,0)+IF(H5<>"미상",1,0)+IF(I5<>"미상",1,0)+IF(J5<>"미상",1,0)+IF(K5<>"미상",1,0)+IF(L5<>"미상",1,0)+IF(M5<>"미상",1,0)+IF(N5<>"미상",1,0))&"/11" -> 11/11 | AC5: 1캡슐 EPA73.3+DHA36.7=110mg(rTG오일146.67mg·순도75%)·멸치류 소형어·d-토코페롤5.4mg·90캡슐 병포장·원료+완제품IFOS5★(TOTOX16.48·산가0.11·중금속통과)·Solutex Omegatex·고양이1알 (상세페이지 실측)
A6: 5 | B6: 묘견서 오메가3 | C6: 펫·캡슐 | D6: 320 | E6: 80 | F6: 명시 | G6: rTG | H6: 소형어 | I6: 있음 | J6: 우수 | K6: 캡슐 | L6: 있음 | M6: 공개 | N6: 명시 | O6: N | P6: N | Q6: N | R6: =IF(NOT(ISNUMBER(D6)),0,IF(D6>=300,20,IF(D6>=200,15,IF(D6>=100,10,5))))+IF(NOT(ISNUMBER(E6)),0,IF(E6>=60,10,IF(E6>=40,6,3)))+IFERROR(VLOOKUP(F6,기준!$B$4:$C$7,2,FALSE()),0) -> 35 | S6: =IFERROR(VLOOKUP(I6,기준!$B$22:$C$24,2,FALSE()),0)+IFERROR(VLOOKUP(J6,기준!$B$27:$C$30,2,FALSE()),0)+IFERROR(VLOOKUP(K6,기준!$B$33:$C$39,2,FALSE()),0) -> 30 | T6: =IFERROR(VLOOKUP(G6,기준!$B$10:$C$13,2,FALSE()),0)+IFERROR(VLOOKUP(H6,기준!$B$16:$C$20,2,FALSE()),0) -> 20 | U6: =IFERROR(VLOOKUP(L6,기준!$B$42:$C$44,2,FALSE()),0)+IFERROR(VLOOKUP(M6,기준!$B$47:$C$50,2,FALSE()),0)+IFERROR(VLOOKUP(N6,기준!$B$53:$C$56,2,FALSE()),0) -> 15 | V6: =SUM(R6:U6) -> 100 | W6: =MIN(IF(O6="Y",20,100),IF(P6="Y",40,100),IF(Q6="Y",50,100)) -> 100 | X6: =MIN(V6,W6) -> 100 | Y6: =RANK(X6,$X$2:$X$34,0) -> 1 | Z6: 공개·검증 | AA6: 관절·신장(EPA우세) | AB6: =(IF(ISNUMBER(D6),1,0)+IF(ISNUMBER(E6),1,0)+IF(F6<>"미상",1,0)+IF(G6<>"미상",1,0)+IF(H6<>"미상",1,0)+IF(I6<>"미상",1,0)+IF(J6<>"미상",1,0)+IF(K6<>"미상",1,0)+IF(L6<>"미상",1,0)+IF(M6<>"미상",1,0)+IF(N6<>"미상",1,0))&"/11" -> 11/11 | AC6: 1캡슐 EPA192+DHA128=320mg(정제어유400mg·순도80%)·rTG·멸치/정어리/고등어·d-토코페롤·PVDC개별포장·IFOS5★완제품+RTCP(TOTOX13.07·산가0.20·중금속통과)·KD파마480320TG (상세페이지 실측)
A7: 6 | B7: 노르딕내추럴스 펫 | C7: 펫·캡슐 | D7: 255 | E7: 26 | F7: 명시 | G7: TG | H7: 소형어 | I7: 있음 | J7: 보통 | K7: 소프트젤 | L7: 미상 | M7: 일부 | N7: 명시 | O7: N | P7: N | Q7: N | R7: =IF(NOT(ISNUMBER(D7)),0,IF(D7>=300,20,IF(D7>=200,15,IF(D7>=100,10,5))))+IF(NOT(ISNUMBER(E7)),0,IF(E7>=60,10,IF(E7>=40,6,3)))+IFERROR(VLOOKUP(F7,기준!$B$4:$C$7,2,FALSE()),0) -> 23 | S7: =IFERROR(VLOOKUP(I7,기준!$B$22:$C$24,2,FALSE()),0)+IFERROR(VLOOKUP(J7,기준!$B$27:$C$30,2,FALSE()),0)+IFERROR(VLOOKUP(K7,기준!$B$33:$C$39,2,FALSE()),0) -> 25 | T7: =IFERROR(VLOOKUP(G7,기준!$B$10:$C$13,2,FALSE()),0)+IFERROR(VLOOKUP(H7,기준!$B$16:$C$20,2,FALSE()),0) -> 20 | U7: =IFERROR(VLOOKUP(L7,기준!$B$42:$C$44,2,FALSE()),0)+IFERROR(VLOOKUP(M7,기준!$B$47:$C$50,2,FALSE()),0)+IFERROR(VLOOKUP(N7,기준!$B$53:$C$56,2,FALSE()),0) -> 7 | V7: =SUM(R7:U7) -> 75 | W7: =MIN(IF(O7="Y",20,100),IF(P7="Y",40,100),IF(Q7="Y",50,100)) -> 100 | X7: =MIN(V7,W7) -> 75 | Y7: =RANK(X7,$X$2:$X$34,0) -> 7 | Z7: 공개·검증 | AA7: 미정 | AB7: =(IF(ISNUMBER(D7),1,0)+IF(ISNUMBER(E7),1,0)+IF(F7<>"미상",1,0)+IF(G7<>"미상",1,0)+IF(H7<>"미상",1,0)+IF(I7<>"미상",1,0)+IF(J7<>"미상",1,0)+IF(K7<>"미상",1,0)+IF(L7<>"미상",1,0)+IF(M7<>"미상",1,0)+IF(N7<>"미상",1,0))&"/11" -> 10/11 | AC7: 1소프트젤 EPA155+DHA100=255mg·멸치/정어리/고등어/청어·TG·토코페롤·배치별 시험공개 (onlynaturalpet/petco)
A8: 7 | B8: 88오메가가드 | C8: 펫·츄 | F8: 미상 | G8: 미상 | H8: 미상 | I8: 미상 | J8: 미상 | K8: 츄 | L8: 미상 | M8: 미상 | N8: 미상 | O8: N | P8: N | Q8: N | R8: =IF(NOT(ISNUMBER(D8)),0,IF(D8>=300,20,IF(D8>=200,15,IF(D8>=100,10,5))))+IF(NOT(ISNUMBER(E8)),0,IF(E8>=60,10,IF(E8>=40,6,3)))+IFERROR(VLOOKUP(F8,기준!$B$4:$C$7,2,FALSE()),0) -> 0 | S8: =IFERROR(VLOOKUP(I8,기준!$B$22:$C$24,2,FALSE()),0)+IFERROR(VLOOKUP(J8,기준!$B$27:$C$30,2,FALSE()),0)+IFERROR(VLOOKUP(K8,기준!$B$33:$C$39,2,FALSE()),0) -> 6 | T8: =IFERROR(VLOOKUP(G8,기준!$B$10:$C$13,2,FALSE()),0)+IFERROR(VLOOKUP(H8,기준!$B$16:$C$20,2,FALSE()),0) -> 8 | U8: =IFERROR(VLOOKUP(L8,기준!$B$42:$C$44,2,FALSE()),0)+IFERROR(VLOOKUP(M8,기준!$B$47:$C$50,2,FALSE()),0)+IFERROR(VLOOKUP(N8,기준!$B$53:$C$56,2,FALSE()),0) -> 0 | V8: =SUM(R8:U8) -> 14 | W8: =MIN(IF(O8="Y",20,100),IF(P8="Y",40,100),IF(Q8="Y",50,100)) -> 100 | X8: =MIN(V8,W8) -> 14 | Y8: =RANK(X8,$X$2:$X$34,0) -> 20 | Z8: 미상 | AA8: 미정 | AB8: =(IF(ISNUMBER(D8),1,0)+IF(ISNUMBER(E8),1,0)+IF(F8<>"미상",1,0)+IF(G8<>"미상",1,0)+IF(H8<>"미상",1,0)+IF(I8<>"미상",1,0)+IF(J8<>"미상",1,0)+IF(K8<>"미상",1,0)+IF(L8<>"미상",1,0)+IF(M8<>"미상",1,0)+IF(N8<>"미상",1,0))&"/11" -> 1/11 | AC8: 씹는 츄·스펙 수집중
A9: 8 | B9: 듀오메가 500mg | C9: 펫·캡슐 | F9: 미상 | G9: 미상 | H9: 미상 | I9: 미상 | J9: 미상 | K9: 캡슐 | L9: 미상 | M9: 미상 | N9: 미상 | O9: N | P9: N | Q9: N | R9: =IF(NOT(ISNUMBER(D9)),0,IF(D9>=300,20,IF(D9>=200,15,IF(D9>=100,10,5))))+IF(NOT(ISNUMBER(E9)),0,IF(E9>=60,10,IF(E9>=40,6,3)))+IFERROR(VLOOKUP(F9,기준!$B$4:$C$7,2,FALSE()),0) -> 0 | S9: =IFERROR(VLOOKUP(I9,기준!$B$22:$C$24,2,FALSE()),0)+IFERROR(VLOOKUP(J9,기준!$B$27:$C$30,2,FALSE()),0)+IFERROR(VLOOKUP(K9,기준!$B$33:$C$39,2,FALSE()),0) -> 10 | T9: =IFERROR(VLOOKUP(G9,기준!$B$10:$C$13,2,FALSE()),0)+IFERROR(VLOOKUP(H9,기준!$B$16:$C$20,2,FALSE()),0) -> 8 | U9: =IFERROR(VLOOKUP(L9,기준!$B$42:$C$44,2,FALSE()),0)+IFERROR(VLOOKUP(M9,기준!$B$47:$C$50,2,FALSE()),0)+IFERROR(VLOOKUP(N9,기준!$B$53:$C$56,2,FALSE()),0) -> 0 | V9: =SUM(R9:U9) -> 18 | W9: =MIN(IF(O9="Y",20,100),IF(P9="Y",40,100),IF(Q9="Y",50,100)) -> 100 | X9: =MIN(V9,W9) -> 18 | Y9: =RANK(X9,$X$2:$X$34,0) -> 17 | Z9: 미상 | AA9: 미정 | AB9: =(IF(ISNUMBER(D9),1,0)+IF(ISNUMBER(E9),1,0)+IF(F9<>"미상",1,0)+IF(G9<>"미상",1,0)+IF(H9<>"미상",1,0)+IF(I9<>"미상",1,0)+IF(J9<>"미상",1,0)+IF(K9<>"미상",1,0)+IF(L9<>"미상",1,0)+IF(M9<>"미상",1,0)+IF(N9<>"미상",1,0))&"/11" -> 1/11 | AC9: 표시 500mg(오일 추정)·EPA+DHA 미상
A10: 9 | B10: 아베텍 오메가3벳 | C10: 펫·캡슐 | F10: 미상 | G10: 미상 | H10: 미상 | I10: 미상 | J10: 미상 | K10: 미상 | L10: 미상 | M10: 미상 | N10: 미상 | O10: N | P10: N | Q10: N | R10: =IF(NOT(ISNUMBER(D10)),0,IF(D10>=300,20,IF(D10>=200,15,IF(D10>=100,10,5))))+IF(NOT(ISNUMBER(E10)),0,IF(E10>=60,10,IF(E10>=40,6,3)))+IFERROR(VLOOKUP(F10,기준!$B$4:$C$7,2,FALSE()),0) -> 0 | S10: =IFERROR(VLOOKUP(I10,기준!$B$22:$C$24,2,FALSE()),0)+IFERROR(VLOOKUP(J10,기준!$B$27:$C$30,2,FALSE()),0)+IFERROR(VLOOKUP(K10,기준!$B$33:$C$39,2,FALSE()),0) -> 0 | T10: =IFERROR(VLOOKUP(G10,기준!$B$10:$C$13,2,FALSE()),0)+IFERROR(VLOOKUP(H10,기준!$B$16:$C$20,2,FALSE()),0) -> 8 | U10: =IFERROR(VLOOKUP(L10,기준!$B$42:$C$44,2,FALSE()),0)+IFERROR(VLOOKUP(M10,기준!$B$47:$C$50,2,FALSE()),0)+IFERROR(VLOOKUP(N10,기준!$B$53:$C$56,2,FALSE()),0) -> 0 | V10: =SUM(R10:U10) -> 8 | W10: =MIN(IF(O10="Y",20,100),IF(P10="Y",40,100),IF(Q10="Y",50,100)) -> 100 | X10: =MIN(V10,W10) -> 8 | Y10: =RANK(X10,$X$2:$X$34,0) -> 25 | Z10: 미상 | AA10: 미정 | AB10: =(IF(ISNUMBER(D10),1,0)+IF(ISNUMBER(E10),1,0)+IF(F10<>"미상",1,0)+IF(G10<>"미상",1,0)+IF(H10<>"미상",1,0)+IF(I10<>"미상",1,0)+IF(J10<>"미상",1,0)+IF(K10<>"미상",1,0)+IF(L10<>"미상",1,0)+IF(M10<>"미상",1,0)+IF(N10<>"미상",1,0))&"/11" -> 0/11 | AC10: 스펙 수집중
A11: 10 | B11: 페스룸 타이니 오메가-3 | C11: 펫 | F11: 미상 | G11: 미상 | H11: 미상 | I11: 미상 | J11: 미상 | K11: 미상 | L11: 미상 | M11: 미상 | N11: 미상 | O11: N | P11: N | Q11: N | R11: =IF(NOT(ISNUMBER(D11)),0,IF(D11>=300,20,IF(D11>=200,15,IF(D11>=100,10,5))))+IF(NOT(ISNUMBER(E11)),0,IF(E11>=60,10,IF(E11>=40,6,3)))+IFERROR(VLOOKUP(F11,기준!$B$4:$C$7,2,FALSE()),0) -> 0 | S11: =IFERROR(VLOOKUP(I11,기준!$B$22:$C$24,2,FALSE()),0)+IFERROR(VLOOKUP(J11,기준!$B$27:$C$30,2,FALSE()),0)+IFERROR(VLOOKUP(K11,기준!$B$33:$C$39,2,FALSE()),0) -> 0 | T11: =IFERROR(VLOOKUP(G11,기준!$B$10:$C$13,2,FALSE()),0)+IFERROR(VLOOKUP(H11,기준!$B$16:$C$20,2,FALSE()),0) -> 8 | U11: =IFERROR(VLOOKUP(L11,기준!$B$42:$C$44,2,FALSE()),0)+IFERROR(VLOOKUP(M11,기준!$B$47:$C$50,2,FALSE()),0)+IFERROR(VLOOKUP(N11,기준!$B$53:$C$56,2,FALSE()),0) -> 0 | V11: =SUM(R11:U11) -> 8 | W11: =MIN(IF(O11="Y",20,100),IF(P11="Y",40,100),IF(Q11="Y",50,100)) -> 100 | X11: =MIN(V11,W11) -> 8 | Y11: =RANK(X11,$X$2:$X$34,0) -> 25 | Z11: 미상 | AA11: 미정 | AB11: =(IF(ISNUMBER(D11),1,0)+IF(ISNUMBER(E11),1,0)+IF(F11<>"미상",1,0)+IF(G11<>"미상",1,0)+IF(H11<>"미상",1,0)+IF(I11<>"미상",1,0)+IF(J11<>"미상",1,0)+IF(K11<>"미상",1,0)+IF(L11<>"미상",1,0)+IF(M11<>"미상",1,0)+IF(N11<>"미상",1,0))&"/11" -> 0/11 | AC11: 스펙 수집중
A12: 11 | B12: 룰루파마 오메가3 | C12: 펫 | F12: 미상 | G12: 미상 | H12: 미상 | I12: 미상 | J12: 미상 | K12: 미상 | L12: 미상 | M12: 미상 | N12: 미상 | O12: N | P12: N | Q12: N | R12: =IF(NOT(ISNUMBER(D12)),0,IF(D12>=300,20,IF(D12>=200,15,IF(D12>=100,10,5))))+IF(NOT(ISNUMBER(E12)),0,IF(E12>=60,10,IF(E12>=40,6,3)))+IFERROR(VLOOKUP(F12,기준!$B$4:$C$7,2,FALSE()),0) -> 0 | S12: =IFERROR(VLOOKUP(I12,기준!$B$22:$C$24,2,FALSE()),0)+IFERROR(VLOOKUP(J12,기준!$B$27:$C$30,2,FALSE()),0)+IFERROR(VLOOKUP(K12,기준!$B$33:$C$39,2,FALSE()),0) -> 0 | T12: =IFERROR(VLOOKUP(G12,기준!$B$10:$C$13,2,FALSE()),0)+IFERROR(VLOOKUP(H12,기준!$B$16:$C$20,2,FALSE()),0) -> 8 | U12: =IFERROR(VLOOKUP(L12,기준!$B$42:$C$44,2,FALSE()),0)+IFERROR(VLOOKUP(M12,기준!$B$47:$C$50,2,FALSE()),0)+IFERROR(VLOOKUP(N12,기준!$B$53:$C$56,2,FALSE()),0) -> 0 | V12: =SUM(R12:U12) -> 8 | W12: =MIN(IF(O12="Y",20,100),IF(P12="Y",40,100),IF(Q12="Y",50,100)) -> 100 | X12: =MIN(V12,W12) -> 8 | Y12: =RANK(X12,$X$2:$X$34,0) -> 25 | Z12: 미상 | AA12: 미정 | AB12: =(IF(ISNUMBER(D12),1,0)+IF(ISNUMBER(E12),1,0)+IF(F12<>"미상",1,0)+IF(G12<>"미상",1,0)+IF(H12<>"미상",1,0)+IF(I12<>"미상",1,0)+IF(J12<>"미상",1,0)+IF(K12<>"미상",1,0)+IF(L12<>"미상",1,0)+IF(M12<>"미상",1,0)+IF(N12<>"미상",1,0))&"/11" -> 0/11 | AC12: 스펙 수집중
A13: 12 | B13: 씽크라이크펫 오메가3 | C13: 펫 | F13: 미상 | G13: 미상 | H13: 미상 | I13: 미상 | J13: 미상 | K13: 미상 | L13: 미상 | M13: 미상 | N13: 미상 | O13: N | P13: N | Q13: N | R13: =IF(NOT(ISNUMBER(D13)),0,IF(D13>=300,20,IF(D13>=200,15,IF(D13>=100,10,5))))+IF(NOT(ISNUMBER(E13)),0,IF(E13>=60,10,IF(E13>=40,6,3)))+IFERROR(VLOOKUP(F13,기준!$B$4:$C$7,2,FALSE()),0) -> 0 | S13: =IFERROR(VLOOKUP(I13,기준!$B$22:$C$24,2,FALSE()),0)+IFERROR(VLOOKUP(J13,기준!$B$27:$C$30,2,FALSE()),0)+IFERROR(VLOOKUP(K13,기준!$B$33:$C$39,2,FALSE()),0) -> 0 | T13: =IFERROR(VLOOKUP(G13,기준!$B$10:$C$13,2,FALSE()),0)+IFERROR(VLOOKUP(H13,기준!$B$16:$C$20,2,FALSE()),0) -> 8 | U13: =IFERROR(VLOOKUP(L13,기준!$B$42:$C$44,2,FALSE()),0)+IFERROR(VLOOKUP(M13,기준!$B$47:$C$50,2,FALSE()),0)+IFERROR(VLOOKUP(N13,기준!$B$53:$C$56,2,FALSE()),0) -> 0 | V13: =SUM(R13:U13) -> 8 | W13: =MIN(IF(O13="Y",20,100),IF(P13="Y",40,100),IF(Q13="Y",50,100)) -> 100 | X13: =MIN(V13,W13) -> 8 | Y13: =RANK(X13,$X$2:$X$34,0) -> 25 | Z13: 미상 | AA13: 미정 | AB13: =(IF(ISNUMBER(D13),1,0)+IF(ISNUMBER(E13),1,0)+IF(F13<>"미상",1,0)+IF(G13<>"미상",1,0)+IF(H13<>"미상",1,0)+IF(I13<>"미상",1,0)+IF(J13<>"미상",1,0)+IF(K13<>"미상",1,0)+IF(L13<>"미상",1,0)+IF(M13<>"미상",1,0)+IF(N13<>"미상",1,0))&"/11" -> 0/11 | AC13: 스펙 수집중
A14: 13 | B14: 이퀄 스틱 오메가3 | C14: 펫·스틱 | F14: 미상 | G14: 미상 | H14: 미상 | I14: 미상 | J14: 미상 | K14: 스틱 | L14: 미상 | M14: 미상 | N14: 미상 | O14: N | P14: N | Q14: N | R14: =IF(NOT(ISNUMBER(D14)),0,IF(D14>=300,20,IF(D14>=200,15,IF(D14>=100,10,5))))+IF(NOT(ISNUMBER(E14)),0,IF(E14>=60,10,IF(E14>=40,6,3)))+IFERROR(VLOOKUP(F14,기준!$B$4:$C$7,2,FALSE()),0) -> 0 | S14: =IFERROR(VLOOKUP(I14,기준!$B$22:$C$24,2,FALSE()),0)+IFERROR(VLOOKUP(J14,기준!$B$27:$C$30,2,FALSE()),0)+IFERROR(VLOOKUP(K14,기준!$B$33:$C$39,2,FALSE()),0) -> 6 | T14: =IFERROR(VLOOKUP(G14,기준!$B$10:$C$13,2,FALSE()),0)+IFERROR(VLOOKUP(H14,기준!$B$16:$C$20,2,FALSE()),0) -> 8 | U14: =IFERROR(VLOOKUP(L14,기준!$B$42:$C$44,2,FALSE()),0)+IFERROR(VLOOKUP(M14,기준!$B$47:$C$50,2,FALSE()),0)+IFERROR(VLOOKUP(N14,기준!$B$53:$C$56,2,FALSE()),0) -> 0 | V14: =SUM(R14:U14) -> 14 | W14: =MIN(IF(O14="Y",20,100),IF(P14="Y",40,100),IF(Q14="Y",50,100)) -> 100 | X14: =MIN(V14,W14) -> 14 | Y14: =RANK(X14,$X$2:$X$34,0) -> 20 | Z14: 라벨만 | AA14: 미정 | AB14: =(IF(ISNUMBER(D14),1,0)+IF(ISNUMBER(E14),1,0)+IF(F14<>"미상",1,0)+IF(G14<>"미상",1,0)+IF(H14<>"미상",1,0)+IF(I14<>"미상",1,0)+IF(J14<>"미상",1,0)+IF(K14<>"미상",1,0)+IF(L14<>"미상",1,0)+IF(M14<>"미상",1,0)+IF(N14<>"미상",1,0))&"/11" -> 1/11 | AC14: 수의사 설계 스틱·초고함량 표방·수치 미상 (이퀄)
A15: 14 | B15: 펫생각 오메가3플러스 | C15: 펫·병원채널 | F15: 미상 | G15: 미상 | H15: 미상 | I15: 미상 | J15: 미상 | K15: 미상 | L15: 미상 | M15: 미상 | N15: 미상 | O15: N | P15: N | Q15: N | R15: =IF(NOT(ISNUMBER(D15)),0,IF(D15>=300,20,IF(D15>=200,15,IF(D15>=100,10,5))))+IF(NOT(ISNUMBER(E15)),0,IF(E15>=60,10,IF(E15>=40,6,3)))+IFERROR(VLOOKUP(F15,기준!$B$4:$C$7,2,FALSE()),0) -> 0 | S15: =IFERROR(VLOOKUP(I15,기준!$B$22:$C$24,2,FALSE()),0)+IFERROR(VLOOKUP(J15,기준!$B$27:$C$30,2,FALSE()),0)+IFERROR(VLOOKUP(K15,기준!$B$33:$C$39,2,FALSE()),0) -> 0 | T15: =IFERROR(VLOOKUP(G15,기준!$B$10:$C$13,2,FALSE()),0)+IFERROR(VLOOKUP(H15,기준!$B$16:$C$20,2,FALSE()),0) -> 8 | U15: =IFERROR(VLOOKUP(L15,기준!$B$42:$C$44,2,FALSE()),0)+IFERROR(VLOOKUP(M15,기준!$B$47:$C$50,2,FALSE()),0)+IFERROR(VLOOKUP(N15,기준!$B$53:$C$56,2,FALSE()),0) -> 0 | V15: =SUM(R15:U15) -> 8 | W15: =MIN(IF(O15="Y",20,100),IF(P15="Y",40,100),IF(Q15="Y",50,100)) -> 100 | X15: =MIN(V15,W15) -> 8 | Y15: =RANK(X15,$X$2:$X$34,0) -> 25 | Z15: 라벨만 | AA15: 미정 | AB15: =(IF(ISNUMBER(D15),1,0)+IF(ISNUMBER(E15),1,0)+IF(F15<>"미상",1,0)+IF(G15<>"미상",1,0)+IF(H15<>"미상",1,0)+IF(I15<>"미상",1,0)+IF(J15<>"미상",1,0)+IF(K15<>"미상",1,0)+IF(L15<>"미상",1,0)+IF(M15<>"미상",1,0)+IF(N15<>"미상",1,0))&"/11" -> 0/11 | AC15: 동물병원협회 추천 (비타트라)
A16: 15 | B16: 펫생각 데일리케얼 오메가3 미니 | C16: 펫 | F16: 미상 | G16: 미상 | H16: 미상 | I16: 미상 | J16: 미상 | K16: 미상 | L16: 미상 | M16: 미상 | N16: 미상 | O16: N | P16: N | Q16: N | R16: =IF(NOT(ISNUMBER(D16)),0,IF(D16>=300,20,IF(D16>=200,15,IF(D16>=100,10,5))))+IF(NOT(ISNUMBER(E16)),0,IF(E16>=60,10,IF(E16>=40,6,3)))+IFERROR(VLOOKUP(F16,기준!$B$4:$C$7,2,FALSE()),0) -> 0 | S16: =IFERROR(VLOOKUP(I16,기준!$B$22:$C$24,2,FALSE()),0)+IFERROR(VLOOKUP(J16,기준!$B$27:$C$30,2,FALSE()),0)+IFERROR(VLOOKUP(K16,기준!$B$33:$C$39,2,FALSE()),0) -> 0 | T16: =IFERROR(VLOOKUP(G16,기준!$B$10:$C$13,2,FALSE()),0)+IFERROR(VLOOKUP(H16,기준!$B$16:$C$20,2,FALSE()),0) -> 8 | U16: =IFERROR(VLOOKUP(L16,기준!$B$42:$C$44,2,FALSE()),0)+IFERROR(VLOOKUP(M16,기준!$B$47:$C$50,2,FALSE()),0)+IFERROR(VLOOKUP(N16,기준!$B$53:$C$56,2,FALSE()),0) -> 0 | V16: =SUM(R16:U16) -> 8 | W16: =MIN(IF(O16="Y",20,100),IF(P16="Y",40,100),IF(Q16="Y",50,100)) -> 100 | X16: =MIN(V16,W16) -> 8 | Y16: =RANK(X16,$X$2:$X$34,0) -> 25 | Z16: 미상 | AA16: 미정 | AB16: =(IF(ISNUMBER(D16),1,0)+IF(ISNUMBER(E16),1,0)+IF(F16<>"미상",1,0)+IF(G16<>"미상",1,0)+IF(H16<>"미상",1,0)+IF(I16<>"미상",1,0)+IF(J16<>"미상",1,0)+IF(K16<>"미상",1,0)+IF(L16<>"미상",1,0)+IF(M16<>"미상",1,0)+IF(N16<>"미상",1,0))&"/11" -> 0/11 | AC16: 미니 SKU·스펙 수집중
A17: 16 | B17: 아이슬란딕 헤링 오메가3 | C17: 펫·액상 | F17: 미상 | G17: 미상 | H17: 소형어 | I17: 미상 | J17: 보통 | K17: 펌프액상 | L17: 미상 | M17: 미상 | N17: 미상 | O17: N | P17: N | Q17: N | R17: =IF(NOT(ISNUMBER(D17)),0,IF(D17>=300,20,IF(D17>=200,15,IF(D17>=100,10,5))))+IF(NOT(ISNUMBER(E17)),0,IF(E17>=60,10,IF(E17>=40,6,3)))+IFERROR(VLOOKUP(F17,기준!$B$4:$C$7,2,FALSE()),0) -> 0 | S17: =IFERROR(VLOOKUP(I17,기준!$B$22:$C$24,2,FALSE()),0)+IFERROR(VLOOKUP(J17,기준!$B$27:$C$30,2,FALSE()),0)+IFERROR(VLOOKUP(K17,기준!$B$33:$C$39,2,FALSE()),0) -> 11 | T17: =IFERROR(VLOOKUP(G17,기준!$B$10:$C$13,2,FALSE()),0)+IFERROR(VLOOKUP(H17,기준!$B$16:$C$20,2,FALSE()),0) -> 15 | U17: =IFERROR(VLOOKUP(L17,기준!$B$42:$C$44,2,FALSE()),0)+IFERROR(VLOOKUP(M17,기준!$B$47:$C$50,2,FALSE()),0)+IFERROR(VLOOKUP(N17,기준!$B$53:$C$56,2,FALSE()),0) -> 0 | V17: =SUM(R17:U17) -> 26 | W17: =MIN(IF(O17="Y",20,100),IF(P17="Y",40,100),IF(Q17="Y",50,100)) -> 100 | X17: =MIN(V17,W17) -> 26 | Y17: =RANK(X17,$X$2:$X$34,0) -> 14 | Z17: 라벨만 | AA17: 미정 | AB17: =(IF(ISNUMBER(D17),1,0)+IF(ISNUMBER(E17),1,0)+IF(F17<>"미상",1,0)+IF(G17<>"미상",1,0)+IF(H17<>"미상",1,0)+IF(I17<>"미상",1,0)+IF(J17<>"미상",1,0)+IF(K17<>"미상",1,0)+IF(L17<>"미상",1,0)+IF(M17<>"미상",1,0)+IF(N17<>"미상",1,0))&"/11" -> 3/11 | AC17: 청어·액상펌프·비산화구조 표방 (비마이펫)
A18: 17 | B18: 바이오펫츠 펫메가3 | C18: 펫·액상 | F18: 미상 | G18: 미상 | H18: 일반어 | I18: 미상 | J18: 우수 | K18: 펌프액상 | L18: 미상 | M18: 미상 | N18: 미상 | O18: N | P18: N | Q18: N | R18: =IF(NOT(ISNUMBER(D18)),0,IF(D18>=300,20,IF(D18>=200,15,IF(D18>=100,10,5))))+IF(NOT(ISNUMBER(E18)),0,IF(E18>=60,10,IF(E18>=40,6,3)))+IFERROR(VLOOKUP(F18,기준!$B$4:$C$7,2,FALSE()),0) -> 0 | S18: =IFERROR(VLOOKUP(I18,기준!$B$22:$C$24,2,FALSE()),0)+IFERROR(VLOOKUP(J18,기준!$B$27:$C$30,2,FALSE()),0)+IFERROR(VLOOKUP(K18,기준!$B$33:$C$39,2,FALSE()),0) -> 16 | T18: =IFERROR(VLOOKUP(G18,기준!$B$10:$C$13,2,FALSE()),0)+IFERROR(VLOOKUP(H18,기준!$B$16:$C$20,2,FALSE()),0) -> 11 | U18: =IFERROR(VLOOKUP(L18,기준!$B$42:$C$44,2,FALSE()),0)+IFERROR(VLOOKUP(M18,기준!$B$47:$C$50,2,FALSE()),0)+IFERROR(VLOOKUP(N18,기준!$B$53:$C$56,2,FALSE()),0) -> 0 | V18: =SUM(R18:U18) -> 27 | W18: =MIN(IF(O18="Y",20,100),IF(P18="Y",40,100),IF(Q18="Y",50,100)) -> 100 | X18: =MIN(V18,W18) -> 27 | Y18: =RANK(X18,$X$2:$X$34,0) -> 13 | Z18: 라벨만 | AA18: 미정 | AB18: =(IF(ISNUMBER(D18),1,0)+IF(ISNUMBER(E18),1,0)+IF(F18<>"미상",1,0)+IF(G18<>"미상",1,0)+IF(H18<>"미상",1,0)+IF(I18<>"미상",1,0)+IF(J18<>"미상",1,0)+IF(K18<>"미상",1,0)+IF(L18<>"미상",1,0)+IF(M18<>"미상",1,0)+IF(N18<>"미상",1,0))&"/11" -> 3/11 | AC18: 연어·액상·공기차단특허
A19: 18 | B19: 브릴리언트 연어오일 1000ml | C19: 펫·액상 | F19: 미상 | G19: 미상 | H19: 일반어 | I19: 미상 | J19: 취약 | K19: 대용량액상 | L19: 미상 | M19: 미상 | N19: 미상 | O19: N | P19: N | Q19: N | R19: =IF(NOT(ISNUMBER(D19)),0,IF(D19>=300,20,IF(D19>=200,15,IF(D19>=100,10,5))))+IF(NOT(ISNUMBER(E19)),0,IF(E19>=60,10,IF(E19>=40,6,3)))+IFERROR(VLOOKUP(F19,기준!$B$4:$C$7,2,FALSE()),0) -> 0 | S19: =IFERROR(VLOOKUP(I19,기준!$B$22:$C$24,2,FALSE()),0)+IFERROR(VLOOKUP(J19,기준!$B$27:$C$30,2,FALSE()),0)+IFERROR(VLOOKUP(K19,기준!$B$33:$C$39,2,FALSE()),0) -> 2 | T19: =IFERROR(VLOOKUP(G19,기준!$B$10:$C$13,2,FALSE()),0)+IFERROR(VLOOKUP(H19,기준!$B$16:$C$20,2,FALSE()),0) -> 11 | U19: =IFERROR(VLOOKUP(L19,기준!$B$42:$C$44,2,FALSE()),0)+IFERROR(VLOOKUP(M19,기준!$B$47:$C$50,2,FALSE()),0)+IFERROR(VLOOKUP(N19,기준!$B$53:$C$56,2,FALSE()),0) -> 0 | V19: =SUM(R19:U19) -> 13 | W19: =MIN(IF(O19="Y",20,100),IF(P19="Y",40,100),IF(Q19="Y",50,100)) -> 100 | X19: =MIN(V19,W19) -> 13 | Y19: =RANK(X19,$X$2:$X$34,0) -> 22 | Z19: 라벨만 | AA19: 미정 | AB19: =(IF(ISNUMBER(D19),1,0)+IF(ISNUMBER(E19),1,0)+IF(F19<>"미상",1,0)+IF(G19<>"미상",1,0)+IF(H19<>"미상",1,0)+IF(I19<>"미상",1,0)+IF(J19<>"미상",1,0)+IF(K19<>"미상",1,0)+IF(L19<>"미상",1,0)+IF(M19<>"미상",1,0)+IF(N19<>"미상",1,0))&"/11" -> 3/11 | AC19: 연어오일 1000ml 대용량 (핏펫)
... A26: 25 | B26: venefit omega3 plus | C26: 병원·클리닉 | F26: 미상 | G26: 미상 | H26: 미상 | I26: 미상 | J26: 미상 | K26: 미상 | L26: 미상 | M26: 미상 | N26: 미상 | O26: N | P26: N | Q26: N | R26: =IF(NOT(ISNUMBER(D26)),0,IF(D26>=300,20,IF(D26>=200,15,IF(D26>=100,10,5))))+IF(NOT(ISNUMBER(E26)),0,IF(E26>=60,10,IF(E26>=40,6,3)))+IFERROR(VLOOKUP(F26,기준!$B$4:$C$7,2,FALSE()),0) -> 0 | S26: =IFERROR(VLOOKUP(I26,기준!$B$22:$C$24,2,FALSE()),0)+IFERROR(VLOOKUP(J26,기준!$B$27:$C$30,2,FALSE()),0)+IFERROR(VLOOKUP(K26,기준!$B$33:$C$39,2,FALSE()),0) -> 0 | T26: =IFERROR(VLOOKUP(G26,기준!$B$10:$C$13,2,FALSE()),0)+IFERROR(VLOOKUP(H26,기준!$B$16:$C$20,2,FALSE()),0) -> 8 | U26: =IFERROR(VLOOKUP(L26,기준!$B$42:$C$44,2,FALSE()),0)+IFERROR(VLOOKUP(M26,기준!$B$47:$C$50,2,FALSE()),0)+IFERROR(VLOOKUP(N26,기준!$B$53:$C$56,2,FALSE()),0) -> 0 | V26: =SUM(R26:U26) -> 8 | W26: =MIN(IF(O26="Y",20,100),IF(P26="Y",40,100),IF(Q26="Y",50,100)) -> 100 | X26: =MIN(V26,W26) -> 8 | Y26: =RANK(X26,$X$2:$X$34,0) -> 25 | Z26: 미상 | AA26: 미정 | AB26: =(IF(ISNUMBER(D26),1,0)+IF(ISNUMBER(E26),1,0)+IF(F26<>"미상",1,0)+IF(G26<>"미상",1,0)+IF(H26<>"미상",1,0)+IF(I26<>"미상",1,0)+IF(J26<>"미상",1,0)+IF(K26<>"미상",1,0)+IF(L26<>"미상",1,0)+IF(M26<>"미상",1,0)+IF(N26<>"미상",1,0))&"/11" -> 0/11 | AC26: 병원 납품·공개정보 적음·수집중
A27: 26 | B27: 스포츠리서치 트리플 스트렝스 | C27: 사람용 | D27: 937 | E27: 75 | F27: 명시 | G27: TG | H27: 소형어 | I27: 미상 | J27: 취약 | K27: 소프트젤 | L27: 있음 | M27: 일부 | N27: 명시 | O27: N | P27: N | Q27: N | R27: =IF(NOT(ISNUMBER(D27)),0,IF(D27>=300,20,IF(D27>=200,15,IF(D27>=100,10,5))))+IF(NOT(ISNUMBER(E27)),0,IF(E27>=60,10,IF(E27>=40,6,3)))+IFERROR(VLOOKUP(F27,기준!$B$4:$C$7,2,FALSE()),0) -> 35 | S27: =IFERROR(VLOOKUP(I27,기준!$B$22:$C$24,2,FALSE()),0)+IFERROR(VLOOKUP(J27,기준!$B$27:$C$30,2,FALSE()),0)+IFERROR(VLOOKUP(K27,기준!$B$33:$C$39,2,FALSE()),0) -> 10 | T27: =IFERROR(VLOOKUP(G27,기준!$B$10:$C$13,2,FALSE()),0)+IFERROR(VLOOKUP(H27,기준!$B$16:$C$20,2,FALSE()),0) -> 20 | U27: =IFERROR(VLOOKUP(L27,기준!$B$42:$C$44,2,FALSE()),0)+IFERROR(VLOOKUP(M27,기준!$B$47:$C$50,2,FALSE()),0)+IFERROR(VLOOKUP(N27,기준!$B$53:$C$56,2,FALSE()),0) -> 12 | V27: =SUM(R27:U27) -> 77 | W27: =MIN(IF(O27="Y",20,100),IF(P27="Y",40,100),IF(Q27="Y",50,100)) -> 100 | X27: =MIN(V27,W27) -> 77 | Y27: =RANK(X27,$X$2:$X$34,0) -> 6 | Z27: 공개·검증 | AA27: 미정 | AB27: =(IF(ISNUMBER(D27),1,0)+IF(ISNUMBER(E27),1,0)+IF(F27<>"미상",1,0)+IF(G27<>"미상",1,0)+IF(H27<>"미상",1,0)+IF(I27<>"미상",1,0)+IF(J27<>"미상",1,0)+IF(K27<>"미상",1,0)+IF(L27<>"미상",1,0)+IF(M27<>"미상",1,0)+IF(N27<>"미상",1,0))&"/11" -> 10/11 | AC27: EPA+DHA 937/캡슐·순도~75%·AlaskaOmega·IFOS·병포장 (필라이즈)
A28: 27 | B28: 종근당 프로메가 알티지 듀얼 | C28: 사람용 | D28: 300 | F28: 명시 | G28: rTG | H28: 미상 | I28: 미상 | J28: 미상 | K28: 캡슐 | L28: 미상 | M28: 미상 | N28: 명시 | O28: N | P28: N | Q28: N | R28: =IF(NOT(ISNUMBER(D28)),0,IF(D28>=300,20,IF(D28>=200,15,IF(D28>=100,10,5))))+IF(NOT(ISNUMBER(E28)),0,IF(E28>=60,10,IF(E28>=40,6,3)))+IFERROR(VLOOKUP(F28,기준!$B$4:$C$7,2,FALSE()),0) -> 25 | S28: =IFERROR(VLOOKUP(I28,기준!$B$22:$C$24,2,FALSE()),0)+IFERROR(VLOOKUP(J28,기준!$B$27:$C$30,2,FALSE()),0)+IFERROR(VLOOKUP(K28,기준!$B$33:$C$39,2,FALSE()),0) -> 10 | T28: =IFERROR(VLOOKUP(G28,기준!$B$10:$C$13,2,FALSE()),0)+IFERROR(VLOOKUP(H28,기준!$B$16:$C$20,2,FALSE()),0) -> 13 | U28: =IFERROR(VLOOKUP(L28,기준!$B$42:$C$44,2,FALSE()),0)+IFERROR(VLOOKUP(M28,기준!$B$47:$C$50,2,FALSE()),0)+IFERROR(VLOOKUP(N28,기준!$B$53:$C$56,2,FALSE()),0) -> 4 | V28: =SUM(R28:U28) -> 52 | W28: =MIN(IF(O28="Y",20,100),IF(P28="Y",40,100),IF(Q28="Y",50,100)) -> 100 | X28: =MIN(V28,W28) -> 52 | Y28: =RANK(X28,$X$2:$X$34,0) -> 8 | Z28: 라벨만 | AA28: 미정 | AB28: =(IF(ISNUMBER(D28),1,0)+IF(ISNUMBER(E28),1,0)+IF(F28<>"미상",1,0)+IF(G28<>"미상",1,0)+IF(H28<>"미상",1,0)+IF(I28<>"미상",1,0)+IF(J28<>"미상",1,0)+IF(K28<>"미상",1,0)+IF(L28<>"미상",1,0)+IF(M28<>"미상",1,0)+IF(N28<>"미상",1,0))&"/11" -> 5/11 | AC28: 1캡슐 EPA+DHA 300mg·rTG·AlaskaOmega·비타민D (소셜타임스/필라이즈)
A29: 28 | B29: 트루엔 알티지 오메가3 | C29: 사람용 | F29: 미상 | G29: rTG | H29: 미상 | I29: 미상 | J29: 미상 | K29: 캡슐 | L29: 미상 | M29: 미상 | N29: 미상 | O29: N | P29: N | Q29: N | R29: =IF(NOT(ISNUMBER(D29)),0,IF(D29>=300,20,IF(D29>=200,15,IF(D29>=100,10,5))))+IF(NOT(ISNUMBER(E29)),0,IF(E29>=60,10,IF(E29>=40,6,3)))+IFERROR(VLOOKUP(F29,기준!$B$4:$C$7,2,FALSE()),0) -> 0 | S29: =IFERROR(VLOOKUP(I29,기준!$B$22:$C$24,2,FALSE()),0)+IFERROR(VLOOKUP(J29,기준!$B$27:$C$30,2,FALSE()),0)+IFERROR(VLOOKUP(K29,기준!$B$33:$C$39,2,FALSE()),0) -> 10 | T29: =IFERROR(VLOOKUP(G29,기준!$B$10:$C$13,2,FALSE()),0)+IFERROR(VLOOKUP(H29,기준!$B$16:$C$20,2,FALSE()),0) -> 13 | U29: =IFERROR(VLOOKUP(L29,기준!$B$42:$C$44,2,FALSE()),0)+IFERROR(VLOOKUP(M29,기준!$B$47:$C$50,2,FALSE()),0)+IFERROR(VLOOKUP(N29,기준!$B$53:$C$56,2,FALSE()),0) -> 0 | V29: =SUM(R29:U29) -> 23 | W29: =MIN(IF(O29="Y",20,100),IF(P29="Y",40,100),IF(Q29="Y",50,100)) -> 100 | X29: =MIN(V29,W29) -> 23 | Y29: =RANK(X29,$X$2:$X$34,0) -> 15 | Z29: 미상 | AA29: 미정 | AB29: =(IF(ISNUMBER(D29),1,0)+IF(ISNUMBER(E29),1,0)+IF(F29<>"미상",1,0)+IF(G29<>"미상",1,0)+IF(H29<>"미상",1,0)+IF(I29<>"미상",1,0)+IF(J29<>"미상",1,0)+IF(K29<>"미상",1,0)+IF(L29<>"미상",1,0)+IF(M29<>"미상",1,0)+IF(N29<>"미상",1,0))&"/11" -> 2/11 | AC29: rTG·스펙 수집중
A30: 29 | B30: 닥터닥터스 알티지 rTG 1200 | C30: 사람용 | F30: 미상 | G30: rTG | H30: 소형어 | I30: 미상 | J30: 미상 | K30: 캡슐 | L30: 있음 | M30: 미상 | N30: 미상 | O30: N | P30: N | Q30: N | R30: =IF(NOT(ISNUMBER(D30)),0,IF(D30>=300,20,IF(D30>=200,15,IF(D30>=100,10,5))))+IF(NOT(ISNUMBER(E30)),0,IF(E30>=60,10,IF(E30>=40,6,3)))+IFERROR(VLOOKUP(F30,기준!$B$4:$C$7,2,FALSE()),0) -> 0 | S30: =IFERROR(VLOOKUP(I30,기준!$B$22:$C$24,2,FALSE()),0)+IFERROR(VLOOKUP(J30,기준!$B$27:$C$30,2,FALSE()),0)+IFERROR(VLOOKUP(K30,기준!$B$33:$C$39,2,FALSE()),0) -> 10 | T30: =IFERROR(VLOOKUP(G30,기준!$B$10:$C$13,2,FALSE()),0)+IFERROR(VLOOKUP(H30,기준!$B$16:$C$20,2,FALSE()),0) -> 20 | U30: =IFERROR(VLOOKUP(L30,기준!$B$42:$C$44,2,FALSE()),0)+IFERROR(VLOOKUP(M30,기준!$B$47:$C$50,2,FALSE()),0)+IFERROR(VLOOKUP(N30,기준!$B$53:$C$56,2,FALSE()),0) -> 5 | V30: =SUM(R30:U30) -> 35 | W30: =MIN(IF(O30="Y",20,100),IF(P30="Y",40,100),IF(Q30="Y",50,100)) -> 100 | X30: =MIN(V30,W30) -> 35 | Y30: =RANK(X30,$X$2:$X$34,0) -> 11 | Z30: 라벨만 | AA30: 미정 | AB30: =(IF(ISNUMBER(D30),1,0)+IF(ISNUMBER(E30),1,0)+IF(F30<>"미상",1,0)+IF(G30<>"미상",1,0)+IF(H30<>"미상",1,0)+IF(I30<>"미상",1,0)+IF(J30<>"미상",1,0)+IF(K30<>"미상",1,0)+IF(L30<>"미상",1,0)+IF(M30<>"미상",1,0)+IF(N30<>"미상",1,0))&"/11" -> 4/11 | AC30: IFOS 5STAR·멸치·rTG·표시1200mg(EPA+DHA 확인필요) (11번가)
A31: 30 | B31: 위타민 알티지 | C31: 사람용 | D31: 980 | F31: 미상 | G31: rTG | H31: 미상 | I31: 미상 | J31: 미상 | K31: 캡슐 | L31: 있음 | M31: 미상 | N31: 미상 | O31: N | P31: N | Q31: N | R31: =IF(NOT(ISNUMBER(D31)),0,IF(D31>=300,20,IF(D31>=200,15,IF(D31>=100,10,5))))+IF(NOT(ISNUMBER(E31)),0,IF(E31>=60,10,IF(E31>=40,6,3)))+IFERROR(VLOOKUP(F31,기준!$B$4:$C$7,2,FALSE()),0) -> 20 | S31: =IFERROR(VLOOKUP(I31,기준!$B$22:$C$24,2,FALSE()),0)+IFERROR(VLOOKUP(J31,기준!$B$27:$C$30,2,FALSE()),0)+IFERROR(VLOOKUP(K31,기준!$B$33:$C$39,2,FALSE()),0) -> 10 | T31: =IFERROR(VLOOKUP(G31,기준!$B$10:$C$13,2,FALSE()),0)+IFERROR(VLOOKUP(H31,기준!$B$16:$C$20,2,FALSE()),0) -> 13 | U31: =IFERROR(VLOOKUP(L31,기준!$B$42:$C$44,2,FALSE()),0)+IFERROR(VLOOKUP(M31,기준!$B$47:$C$50,2,FALSE()),0)+IFERROR(VLOOKUP(N31,기준!$B$53:$C$56,2,FALSE()),0) -> 5 | V31: =SUM(R31:U31) -> 48 | W31: =MIN(IF(O31="Y",20,100),IF(P31="Y",40,100),IF(Q31="Y",50,100)) -> 100 | X31: =MIN(V31,W31) -> 48 | Y31: =RANK(X31,$X$2:$X$34,0) -> 9 | Z31: 공개·검증 | AA31: 미정 | AB31: =(IF(ISNUMBER(D31),1,0)+IF(ISNUMBER(E31),1,0)+IF(F31<>"미상",1,0)+IF(G31<>"미상",1,0)+IF(H31<>"미상",1,0)+IF(I31<>"미상",1,0)+IF(J31<>"미상",1,0)+IF(K31<>"미상",1,0)+IF(L31<>"미상",1,0)+IF(M31<>"미상",1,0)+IF(N31<>"미상",1,0))&"/11" -> 4/11 | AC31: 완제품 IFOS·EPA+DHA 980mg·rTG (위타민)
A32: 31 | B32: 캘리포니아골드 뉴트리션 오메가3 | C32: 사람용 | D32: 300 | E32: 60 | F32: 명시 | G32: TG | H32: 소형어 | I32: 있음 | J32: 취약 | K32: 소프트젤 | L32: 미상 | M32: 일부 | N32: 미상 | O32: N | P32: N | Q32: N | R32: =IF(NOT(ISNUMBER(D32)),0,IF(D32>=300,20,IF(D32>=200,15,IF(D32>=100,10,5))))+IF(NOT(ISNUMBER(E32)),0,IF(E32>=60,10,IF(E32>=40,6,3)))+IFERROR(VLOOKUP(F32,기준!$B$4:$C$7,2,FALSE()),0) -> 35 | S32: =IFERROR(VLOOKUP(I32,기준!$B$22:$C$24,2,FALSE()),0)+IFERROR(VLOOKUP(J32,기준!$B$27:$C$30,2,FALSE()),0)+IFERROR(VLOOKUP(K32,기준!$B$33:$C$39,2,FALSE()),0) -> 20 | T32: =IFERROR(VLOOKUP(G32,기준!$B$10:$C$13,2,FALSE()),0)+IFERROR(VLOOKUP(H32,기준!$B$16:$C$20,2,FALSE()),0) -> 20 | U32: =IFERROR(VLOOKUP(L32,기준!$B$42:$C$44,2,FALSE()),0)+IFERROR(VLOOKUP(M32,기준!$B$47:$C$50,2,FALSE()),0)+IFERROR(VLOOKUP(N32,기준!$B$53:$C$56,2,FALSE()),0) -> 3 | V32: =SUM(R32:U32) -> 78 | W32: =MIN(IF(O32="Y",20,100),IF(P32="Y",40,100),IF(Q32="Y",50,100)) -> 100 | X32: =MIN(V32,W32) -> 78 | Y32: =RANK(X32,$X$2:$X$34,0) -> 5 | Z32: 공개·검증 | AA32: 미정 | AB32: =(IF(ISNUMBER(D32),1,0)+IF(ISNUMBER(E32),1,0)+IF(F32<>"미상",1,0)+IF(G32<>"미상",1,0)+IF(H32<>"미상",1,0)+IF(I32<>"미상",1,0)+IF(J32<>"미상",1,0)+IF(K32<>"미상",1,0)+IF(L32<>"미상",1,0)+IF(M32<>"미상",1,0)+IF(N32<>"미상",1,0))&"/11" -> 9/11 | AC32: 1캡슐 EPA180+DHA120=300mg(총500mg·순도60%)·멸치/고등어/정어리/참치·농축TG·비타민E·중금속/PCB시험 (iHerb)
A33: 32 | B33: 담백하루 초임계 알티지 1000 | C33: 사람용 | F33: 미상 | G33: rTG | H33: 미상 | I33: 미상 | J33: 미상 | K33: 캡슐 | L33: 미상 | M33: 미상 | N33: 미상 | O33: N | P33: N | Q33: N | R33: =IF(NOT(ISNUMBER(D33)),0,IF(D33>=300,20,IF(D33>=200,15,IF(D33>=100,10,5))))+IF(NOT(ISNUMBER(E33)),0,IF(E33>=60,10,IF(E33>=40,6,3)))+IFERROR(VLOOKUP(F33,기준!$B$4:$C$7,2,FALSE()),0) -> 0 | S33: =IFERROR(VLOOKUP(I33,기준!$B$22:$C$24,2,FALSE()),0)+IFERROR(VLOOKUP(J33,기준!$B$27:$C$30,2,FALSE()),0)+IFERROR(VLOOKUP(K33,기준!$B$33:$C$39,2,FALSE()),0) -> 10 | T33: =IFERROR(VLOOKUP(G33,기준!$B$10:$C$13,2,FALSE()),0)+IFERROR(VLOOKUP(H33,기준!$B$16:$C$20,2,FALSE()),0) -> 13 | U33: =IFERROR(VLOOKUP(L33,기준!$B$42:$C$44,2,FALSE()),0)+IFERROR(VLOOKUP(M33,기준!$B$47:$C$50,2,FALSE()),0)+IFERROR(VLOOKUP(N33,기준!$B$53:$C$56,2,FALSE()),0) -> 0 | V33: =SUM(R33:U33) -> 23 | W33: =MIN(IF(O33="Y",20,100),IF(P33="Y",40,100),IF(Q33="Y",50,100)) -> 100 | X33: =MIN(V33,W33) -> 23 | Y33: =RANK(X33,$X$2:$X$34,0) -> 15 | Z33: 미상 | AA33: 미정 | AB33: =(IF(ISNUMBER(D33),1,0)+IF(ISNUMBER(E33),1,0)+IF(F33<>"미상",1,0)+IF(G33<>"미상",1,0)+IF(H33<>"미상",1,0)+IF(I33<>"미상",1,0)+IF(J33<>"미상",1,0)+IF(K33<>"미상",1,0)+IF(L33<>"미상",1,0)+IF(M33<>"미상",1,0)+IF(N33<>"미상",1,0))&"/11" -> 2/11 | AC33: 초임계 rTG·스펙 수집중
A34: 33 | B34: 고려은단 식물성 퓨어 알티지 | C34: 사람용·식물성 | F34: 미상 | G34: rTG | H34: 조류 | I34: 미상 | J34: 미상 | K34: 캡슐 | L34: 미상 | M34: 미상 | N34: 미상 | O34: N | P34: N | Q34: N | R34: =IF(NOT(ISNUMBER(D34)),0,IF(D34>=300,20,IF(D34>=200,15,IF(D34>=100,10,5))))+IF(NOT(ISNUMBER(E34)),0,IF(E34>=60,10,IF(E34>=40,6,3)))+IFERROR(VLOOKUP(F34,기준!$B$4:$C$7,2,FALSE()),0) -> 0 | S34: =IFERROR(VLOOKUP(I34,기준!$B$22:$C$24,2,FALSE()),0)+IFERROR(VLOOKUP(J34,기준!$B$27:$C$30,2,FALSE()),0)+IFERROR(VLOOKUP(K34,기준!$B$33:$C$39,2,FALSE()),0) -> 10 | T34: =IFERROR(VLOOKUP(G34,기준!$B$10:$C$13,2,FALSE()),0)+IFERROR(VLOOKUP(H34,기준!$B$16:$C$20,2,FALSE()),0) -> 18 | U34: =IFERROR(VLOOKUP(L34,기준!$B$42:$C$44,2,FALSE()),0)+IFERROR(VLOOKUP(M34,기준!$B$47:$C$50,2,FALSE()),0)+IFERROR(VLOOKUP(N34,기준!$B$53:$C$56,2,FALSE()),0) -> 0 | V34: =SUM(R34:U34) -> 28 | W34: =MIN(IF(O34="Y",20,100),IF(P34="Y",40,100),IF(Q34="Y",50,100)) -> 100 | X34: =MIN(V34,W34) -> 28 | Y34: =RANK(X34,$X$2:$X$34,0) -> 12 | Z34: 라벨만 | AA34: DHA중심(조류) | AB34: =(IF(ISNUMBER(D34),1,0)+IF(ISNUMBER(E34),1,0)+IF(F34<>"미상",1,0)+IF(G34<>"미상",1,0)+IF(H34<>"미상",1,0)+IF(I34<>"미상",1,0)+IF(J34<>"미상",1,0)+IF(K34<>"미상",1,0)+IF(L34<>"미상",1,0)+IF(M34<>"미상",1,0)+IF(N34<>"미상",1,0))&"/11" -> 3/11 | AC34: 배양 미세조류 유래 EPA/DHA=고양이 사용 가능·DHA 편중·상한 부적용 (소셜타임스)
