Workbook

Sheet 기준
A1: 고양이 오메가3 제품 채점 기준 (공개정보 기반·실측 전)
A2: 가중치 성분35/산패30/원료·형태20/투명성15 | 안전상한 비해양성(ALA)→20·대구간유/비타민A·D→40·산패고위험→50 | 조류오일=정상, 폴락=어체유(간유 아님)
B3: 비율표기
B4: 명시 | C4: 5
B5: 일부 | C5: 2
B6: 미표기 | C6: 0
B7: 미상 | C7: 0
B9: 형태
B10: rTG | C10: 10
B11: TG | C11: 10
B12: EE | C12: 5
B13: 미상 | C13: 5
B15: 어종
B16: 소형어 | C16: 10
B17: 일반어 | C17: 6
B18: 해양포유류 | C18: 6
B19: 식물성 | C19: 0
B20: 조류 | C20: 8
B21: 미상 | C21: 3
B23: 항산화제
B24: 있음 | C24: 10
B25: 없음 | C25: 0
B26: 미상 | C26: 0
B28: 포장
B29: 우수 | C29: 10
B30: 보통 | C30: 5
B31: 취약 | C31: 0
B32: 미상 | C32: 0
B34: 제형
B35: 캡슐 | C35: 10
B36: 소프트젤 | C36: 10
B37: 츄 | C37: 6
B38: 스틱 | C38: 6
B39: 펌프액상 | C39: 6
B40: 대용량액상 | C40: 2
B41: 미상 | C41: 0
B43: 인증
B44: 있음 | C44: 5
B45: 없음 | C45: 0
B46: 미상 | C46: 0
...

Sheet 점수표
A1: 번호 | B1: 제품명 | C1: 분류 | D1: 밀도(EPA+DHA mg/단위) | E1: 순도(%) | F1: 비율표기 | G1: 형태 | H1: 어종 | I1: 항산화제 | J1: 포장 | K1: 제형 | L1: 인증 | M1: COA | N1: 원료사 | O1: 비해양성 | P1: 대구 | Q1: 산패고위험 | R1: 비타민AD | S1: 성분/35 | T1: 산패/30 | U1: 원료형태/20 | V1: 투명성/15 | W1: 합계 | X1: 안전상한 | Y1: 최종점수 | Z1: 잠정순위 | AA1: 정보검증 | AB1: 적합성 | AC1: 데이터충실도 | AD1: 출처·비고
A2: 1 | B2: 닥터레이 오메가3 | C2: 펫·캡슐 | D2: 200 | E2: 80 | F2: 명시 | G2: rTG | H2: 소형어 | I2: 있음 | J2: 우수 | K2: 캡슐 | L2: 있음 | M2: 공개 | N2: 명시 | O2: =IF(H2="식물성","Y","N") | P2: N | Q2: =IF(AND(J2="취약",I2<>"있음",OR(M2="없음",M2="미상")),"Y","N") | R2: N | S2: =IF(NOT(ISNUMBER(D2)),0,IF(D2>=300,20,IF(D2>=200,15,IF(D2>=100,10,5))))+IF(NOT(ISNUMBER(E2)),0,IF(E2>=60,10,IF(E2>=40,6,3)))+IFERROR(VLOOKUP(F2,기준!$B$4:$C$7,2,FALSE),0) | T2: =IFERROR(VLOOKUP(I2,기준!$B$24:$C$26,2,FALSE),0)+IFERROR(VLOOKUP(J2,기준!$B$29:$C$32,2,FALSE),0)+IFERROR(VLOOKUP(K2,기준!$B$35:$C$41,2,FALSE),0) | U2: =IFERROR(VLOOKUP(G2,기준!$B$10:$C$13,2,FALSE),0)+IFERROR(VLOOKUP(H2,기준!$B$16:$C$21,2,FALSE),0) | V2: =IFERROR(VLOOKUP(L2,기준!$B$44:$C$46,2,FALSE),0)+IFERROR(VLOOKUP(M2,기준!$B$49:$C$52,2,FALSE),0)+IFERROR(VLOOKUP(N2,기준!$B$55:$C$58,2,FALSE),0) | W2: =SUM(S2:V2) | X2: =MIN(IF(O2="Y",20,100),IF(P2="Y",40,100),IF(Q2="Y",50,100),IF(R2="Y",40,100)) | Y2: =MIN(W2,X2) | Z2: =RANK(Y2,$Y$2:$Y$34,0) | AA2: 공개·검증 | AB2: 관절·신장(EPA우세) | AC2: =(IF(ISNUMBER(D2),1,0)+IF(ISNUMBER(E2),1,0)+IF(AND(F2<>"미상",F2<>""),1,0)+IF(AND(G2<>"미상",G2<>""),1,0)+IF(AND(H2<>"미상",H2<>""),1,0)+IF(AND(I2<>"미상",I2<>""),1,0)+IF(AND(J2<>"미상",J2<>""),1,0)+IF(AND(K2<>"미상",K2<>""),1,0)+IF(AND(L2<>"미상",L2<>""),1,0)+IF(AND(M2<>"미상",M2<>""),1,0)+IF(AND(N2<>"미상",N2<>""),1,0))&"/11" | AD2: 1캡슐 EPA120+DHA80=200mg·순도80%·rTG·멸치/정어리·d-토코페롤·PVDC블리스터·IFOS5★완제품(TOTOX10.32·산가0.17·중금속통과)·KD파마/로빈슨파마 (상세페이지 실측)
A3: 2 | B3: 조공 rTG 퓨어 오메가3 | C3: 펫·캡슐 | E3: 80 | F3: 미상 | G3: rTG | H3: 미상 | I3: 미상 | J3: 미상 | K3: 캡슐 | L3: 있음 | M3: 일부 | N3: 명시 | O3: =IF(H3="식물성","Y","N") | P3: N | Q3: =IF(AND(J3="취약",I3<>"있음",OR(M3="없음",M3="미상")),"Y","N") | R3: N | S3: =IF(NOT(ISNUMBER(D3)),0,IF(D3>=300,20,IF(D3>=200,15,IF(D3>=100,10,5))))+IF(NOT(ISNUMBER(E3)),0,IF(E3>=60,10,IF(E3>=40,6,3)))+IFERROR(VLOOKUP(F3,기준!$B$4:$C$7,2,FALSE),0) | T3: =IFERROR(VLOOKUP(I3,기준!$B$24:$C$26,2,FALSE),0)+IFERROR(VLOOKUP(J3,기준!$B$29:$C$32,2,FALSE),0)+IFERROR(VLOOKUP(K3,기준!$B$35:$C$41,2,FALSE),0) | U3: =IFERROR(VLOOKUP(G3,기준!$B$10:$C$13,2,FALSE),0)+IFERROR(VLOOKUP(H3,기준!$B$16:$C$21,2,FALSE),0) | V3: =IFERROR(VLOOKUP(L3,기준!$B$44:$C$46,2,FALSE),0)+IFERROR(VLOOKUP(M3,기준!$B$49:$C$52,2,FALSE),0)+IFERROR(VLOOKUP(N3,기준!$B$55:$C$58,2,FALSE),0) | W3: =SUM(S3:V3) | X3: =MIN(IF(O3="Y",20,100),IF(P3="Y",40,100),IF(Q3="Y",50,100),IF(R3="Y",40,100)) | Y3: =MIN(W3,X3) | Z3: =RANK(Y3,$Y$2:$Y$34,0) | AA3: 공개·검증 | AB3: 미정 | AC3: =(IF(ISNUMBER(D3),1,0)+IF(ISNUMBER(E3),1,0)+IF(AND(F3<>"미상",F3<>""),1,0)+IF(AND(G3<>"미상",G3<>""),1,0)+IF(AND(H3<>"미상",H3<>""),1,0)+IF(AND(I3<>"미상",I3<>""),1,0)+IF(AND(J3<>"미상",J3<>""),1,0)+IF(AND(K3<>"미상",K3<>""),1,0)+IF(AND(L3<>"미상",L3<>""),1,0)+IF(AND(M3<>"미상",M3<>""),1,0)+IF(AND(N3<>"미상",N3<>""),1,0))&"/11" | AD3: IFOS 5-star·Solutex·순도80%+ (모굿인)
A4: 3 | B4: 조공 레드 오메가3 미니 | C4: 펫·캡슐 | D4: 110 | E4: 80 | F4: 명시 | G4: rTG | H4: 소형어 | I4: 있음 | J4: 우수 | K4: 캡슐 | L4: 있음 | M4: 공개 | N4: 명시 | O4: =IF(H4="식물성","Y","N") | P4: N | Q4: =IF(AND(J4="취약",I4<>"있음",OR(M4="없음",M4="미상")),"Y","N") | R4: N | S4: =IF(NOT(ISNUMBER(D4)),0,IF(D4>=300,20,IF(D4>=200,15,IF(D4>=100,10,5))))+IF(NOT(ISNUMBER(E4)),0,IF(E4>=60,10,IF(E4>=40,6,3)))+IFERROR(VLOOKUP(F4,기준!$B$4:$C$7,2,FALSE),0) | T4: =IFERROR(VLOOKUP(I4,기준!$B$24:$C$26,2,FALSE),0)+IFERROR(VLOOKUP(J4,기준!$B$29:$C$32,2,FALSE),0)+IFERROR(VLOOKUP(K4,기준!$B$35:$C$41,2,FALSE),0) | U4: =IFERROR(VLOOKUP(G4,기준!$B$10:$C$13,2,FALSE),0)+IFERROR(VLOOKUP(H4,기준!$B$16:$C$21,2,FALSE),0) | V4: =IFERROR(VLOOKUP(L4,기준!$B$44:$C$46,2,FALSE),0)+IFERROR(VLOOKUP(M4,기준!$B$49:$C$52,2,FALSE),0)+IFERROR(VLOOKUP(N4,기준!$B$55:$C$58,2,FALSE),0) | W4: =SUM(S4:V4) | X4: =MIN(IF(O4="Y",20,100),IF(P4="Y",40,100),IF(Q4="Y",50,100),IF(R4="Y",40,100)) | Y4: =MIN(W4,X4) | Z4: =RANK(Y4,$Y$2:$Y$34,0) | AA4: 공개·검증 | AB4: 일반유지·피부(아스타잔틴) | AC4: =(IF(ISNUMBER(D4),1,0)+IF(ISNUMBER(E4),1,0)+IF(AND(F4<>"미상",F4<>""),1,0)+IF(AND(G4<>"미상",G4<>""),1,0)+IF(AND(H4<>"미상",H4<>""),1,0)+IF(AND(I4<>"미상",I4<>""),1,0)+IF(AND(J4<>"미상",J4<>""),1,0)+IF(AND(K4<>"미상",K4<>""),1,0)+IF(AND(L4<>"미상",L4<>""),1,0)+IF(AND(M4<>"미상",M4<>""),1,0)+IF(AND(N4<>"미상",N4<>""),1,0))&"/11" | AD4: 1캡슐 EPA66+DHA44=110mg(rTG오일137.6mg·순도80%)·멸치류 소형어·아스타잔틴5mg+d-토코페롤·블리스터개별포장·원료+완제품IFOS5★(TOTOX16.49·산가0.27·중금속통과)·Solutex/Viva제조·고양이1알 (상세페이지 실측)
A5: 4 | B5: 조공 데일리 퓨어 오메가-3 미니 | C5: 펫·캡슐 | D5: 110 | E5: 75 | F5: 명시 | G5: rTG | H5: 소형어 | I5: 있음 | J5: 보통 | K5: 캡슐 | L5: 있음 | M5: 공개 | N5: 명시 | O5: =IF(H5="식물성","Y","N") | P5: N | Q5: =IF(AND(J5="취약",I5<>"있음",OR(M5="없음",M5="미상")),"Y","N") | R5: N | S5: =IF(NOT(ISNUMBER(D5)),0,IF(D5>=300,20,IF(D5>=200,15,IF(D5>=100,10,5))))+IF(NOT(ISNUMBER(E5)),0,IF(E5>=60,10,IF(E5>=40,6,3)))+IFERROR(VLOOKUP(F5,기준!$B$4:$C$7,2,FALSE),0) | T5: =IFERROR(VLOOKUP(I5,기준!$B$24:$C$26,2,FALSE),0)+IFERROR(VLOOKUP(J5,기준!$B$29:$C$32,2,FALSE),0)+IFERROR(VLOOKUP(K5,기준!$B$35:$C$41,2,FALSE),0) | U5: =IFERROR(VLOOKUP(G5,기준!$B$10:$C$13,2,FALSE),0)+IFERROR(VLOOKUP(H5,기준!$B$16:$C$21,2,FALSE),0) | V5: =IFERROR(VLOOKUP(L5,기준!$B$44:$C$46,2,FALSE),0)+IFERROR(VLOOKUP(M5,기준!$B$49:$C$52,2,FALSE),0)+IFERROR(VLOOKUP(N5,기준!$B$55:$C$58,2,FALSE),0) | W5: =SUM(S5:V5) | X5: =MIN(IF(O5="Y",20,100),IF(P5="Y",40,100),IF(Q5="Y",50,100),IF(R5="Y",40,100)) | Y5: =MIN(W5,X5) | Z5: =RANK(Y5,$Y$2:$Y$34,0) | AA5: 공개·검증 | AB5: 일반유지(EPA 2:1) | AC5: =(IF(ISNUMBER(D5),1,0)+IF(ISNUMBER(E5),1,0)+IF(AND(F5<>"미상",F5<>""),1,0)+IF(AND(G5<>"미상",G5<>""),1,0)+IF(AND(H5<>"미상",H5<>""),1,0)+IF(AND(I5<>"미상",I5<>""),1,0)+IF(AND(J5<>"미상",J5<>""),1,0)+IF(AND(K5<>"미상",K5<>""),1,0)+IF(AND(L5<>"미상",L5<>""),1,0)+IF(AND(M5<>"미상",M5<>""),1,0)+IF(AND(N5<>"미상",N5<>""),1,0))&"/11" | AD5: 1캡슐 EPA73.3+DHA36.7=110mg(rTG오일146.67mg·순도75%)·멸치류 소형어·d-토코페롤5.4mg·90캡슐 병포장·원료+완제품IFOS5★(TOTOX16.48·산가0.11·중금속통과)·Solutex Omegatex·고양이1알 (상세페이지 실측)
A6: 5 | B6: 묘견서 오메가3 | C6: 펫·캡슐 | D6: 320 | E6: 80 | F6: 명시 | G6: rTG | H6: 소형어 | I6: 있음 | J6: 우수 | K6: 캡슐 | L6: 있음 | M6: 공개 | N6: 명시 | O6: =IF(H6="식물성","Y","N") | P6: N | Q6: =IF(AND(J6="취약",I6<>"있음",OR(M6="없음",M6="미상")),"Y","N") | R6: N | S6: =IF(NOT(ISNUMBER(D6)),0,IF(D6>=300,20,IF(D6>=200,15,IF(D6>=100,10,5))))+IF(NOT(ISNUMBER(E6)),0,IF(E6>=60,10,IF(E6>=40,6,3)))+IFERROR(VLOOKUP(F6,기준!$B$4:$C$7,2,FALSE),0) | T6: =IFERROR(VLOOKUP(I6,기준!$B$24:$C$26,2,FALSE),0)+IFERROR(VLOOKUP(J6,기준!$B$29:$C$32,2,FALSE),0)+IFERROR(VLOOKUP(K6,기준!$B$35:$C$41,2,FALSE),0) | U6: =IFERROR(VLOOKUP(G6,기준!$B$10:$C$13,2,FALSE),0)+IFERROR(VLOOKUP(H6,기준!$B$16:$C$21,2,FALSE),0) | V6: =IFERROR(VLOOKUP(L6,기준!$B$44:$C$46,2,FALSE),0)+IFERROR(VLOOKUP(M6,기준!$B$49:$C$52,2,FALSE),0)+IFERROR(VLOOKUP(N6,기준!$B$55:$C$58,2,FALSE),0) | W6: =SUM(S6:V6) | X6: =MIN(IF(O6="Y",20,100),IF(P6="Y",40,100),IF(Q6="Y",50,100),IF(R6="Y",40,100)) | Y6: =MIN(W6,X6) | Z6: =RANK(Y6,$Y$2:$Y$34,0) | AA6: 공개·검증 | AB6: 관절·신장(EPA우세) | AC6: =(IF(ISNUMBER(D6),1,0)+IF(ISNUMBER(E6),1,0)+IF(AND(F6<>"미상",F6<>""),1,0)+IF(AND(G6<>"미상",G6<>""),1,0)+IF(AND(H6<>"미상",H6<>""),1,0)+IF(AND(I6<>"미상",I6<>""),1,0)+IF(AND(J6<>"미상",J6<>""),1,0)+IF(AND(K6<>"미상",K6<>""),1,0)+IF(AND(L6<>"미상",L6<>""),1,0)+IF(AND(M6<>"미상",M6<>""),1,0)+IF(AND(N6<>"미상",N6<>""),1,0))&"/11" | AD6: 1캡슐 EPA192+DHA128=320mg(정제어유400mg·순도80%)·rTG·멸치/정어리/고등어·d-토코페롤·PVDC개별포장·IFOS5★완제품+RTCP(TOTOX13.07·산가0.20·중금속통과)·KD파마480320TG (상세페이지 실측)
A7: 6 | B7: 노르딕내추럴스 펫 | C7: 펫·캡슐 | D7: 255 | E7: 26 | F7: 명시 | G7: TG | H7: 소형어 | I7: 있음 | J7: 보통 | K7: 소프트젤 | L7: 미상 | M7: 일부 | N7: 명시 | O7: =IF(H7="식물성","Y","N") | P7: N | Q7: =IF(AND(J7="취약",I7<>"있음",OR(M7="없음",M7="미상")),"Y","N") | R7: N | S7: =IF(NOT(ISNUMBER(D7)),0,IF(D7>=300,20,IF(D7>=200,15,IF(D7>=100,10,5))))+IF(NOT(ISNUMBER(E7)),0,IF(E7>=60,10,IF(E7>=40,6,3)))+IFERROR(VLOOKUP(F7,기준!$B$4:$C$7,2,FALSE),0) | T7: =IFERROR(VLOOKUP(I7,기준!$B$24:$C$26,2,FALSE),0)+IFERROR(VLOOKUP(J7,기준!$B$29:$C$32,2,FALSE),0)+IFERROR(VLOOKUP(K7,기준!$B$35:$C$41,2,FALSE),0) | U7: =IFERROR(VLOOKUP(G7,기준!$B$10:$C$13,2,FALSE),0)+IFERROR(VLOOKUP(H7,기준!$B$16:$C$21,2,FALSE),0) | V7: =IFERROR(VLOOKUP(L7,기준!$B$44:$C$46,2,FALSE),0)+IFERROR(VLOOKUP(M7,기준!$B$49:$C$52,2,FALSE),0)+IFERROR(VLOOKUP(N7,기준!$B$55:$C$58,2,FALSE),0) | W7: =SUM(S7:V7) | X7: =MIN(IF(O7="Y",20,100),IF(P7="Y",40,100),IF(Q7="Y",50,100),IF(R7="Y",40,100)) | Y7: =MIN(W7,X7) | Z7: =RANK(Y7,$Y$2:$Y$34,0) | AA7: 공개·검증 | AB7: 미정 | AC7: =(IF(ISNUMBER(D7),1,0)+IF(ISNUMBER(E7),1,0)+IF(AND(F7<>"미상",F7<>""),1,0)+IF(AND(G7<>"미상",G7<>""),1,0)+IF(AND(H7<>"미상",H7<>""),1,0)+IF(AND(I7<>"미상",I7<>""),1,0)+IF(AND(J7<>"미상",J7<>""),1,0)+IF(AND(K7<>"미상",K7<>""),1,0)+IF(AND(L7<>"미상",L7<>""),1,0)+IF(AND(M7<>"미상",M7<>""),1,0)+IF(AND(N7<>"미상",N7<>""),1,0))&"/11" | AD7: 1소프트젤 EPA155+DHA100=255mg·멸치/정어리/고등어/청어·TG·토코페롤·배치별 시험공개 (onlynaturalpet/petco)
A8: 7 | B8: 88오메가가드 | C8: 펫·츄 | F8: 미상 | G8: 미상 | H8: 미상 | I8: 미상 | J8: 미상 | K8: 츄 | L8: 미상 | M8: 미상 | N8: 미상 | O8: =IF(H8="식물성","Y","N") | P8: N | Q8: =IF(AND(J8="취약",I8<>"있음",OR(M8="없음",M8="미상")),"Y","N") | R8: N | S8: =IF(NOT(ISNUMBER(D8)),0,IF(D8>=300,20,IF(D8>=200,15,IF(D8>=100,10,5))))+IF(NOT(ISNUMBER(E8)),0,IF(E8>=60,10,IF(E8>=40,6,3)))+IFERROR(VLOOKUP(F8,기준!$B$4:$C$7,2,FALSE),0) | T8: =IFERROR(VLOOKUP(I8,기준!$B$24:$C$26,2,FALSE),0)+IFERROR(VLOOKUP(J8,기준!$B$29:$C$32,2,FALSE),0)+IFERROR(VLOOKUP(K8,기준!$B$35:$C$41,2,FALSE),0) | U8: =IFERROR(VLOOKUP(G8,기준!$B$10:$C$13,2,FALSE),0)+IFERROR(VLOOKUP(H8,기준!$B$16:$C$21,2,FALSE),0) | V8: =IFERROR(VLOOKUP(L8,기준!$B$44:$C$46,2,FALSE),0)+IFERROR(VLOOKUP(M8,기준!$B$49:$C$52,2,FALSE),0)+IFERROR(VLOOKUP(N8,기준!$B$55:$C$58,2,FALSE),0) | W8: =SUM(S8:V8) | X8: =MIN(IF(O8="Y",20,100),IF(P8="Y",40,100),IF(Q8="Y",50,100),IF(R8="Y",40,100)) | Y8: =MIN(W8,X8) | Z8: =RANK(Y8,$Y$2:$Y$34,0) | AA8: 미상 | AB8: 미정 | AC8: =(IF(ISNUMBER(D8),1,0)+IF(ISNUMBER(E8),1,0)+IF(AND(F8<>"미상",F8<>""),1,0)+IF(AND(G8<>"미상",G8<>""),1,0)+IF(AND(H8<>"미상",H8<>""),1,0)+IF(AND(I8<>"미상",I8<>""),1,0)+IF(AND(J8<>"미상",J8<>""),1,0)+IF(AND(K8<>"미상",K8<>""),1,0)+IF(AND(L8<>"미상",L8<>""),1,0)+IF(AND(M8<>"미상",M8<>""),1,0)+IF(AND(N8<>"미상",N8<>""),1,0))&"/11" | AD8: 씹는 츄·스펙 수집중
A9: 8 | B9: 듀오메가 500mg | C9: 펫·캡슐 | F9: 미상 | G9: 미상 | H9: 미상 | I9: 미상 | J9: 미상 | K9: 캡슐 | L9: 미상 | M9: 미상 | N9: 미상 | O9: =IF(H9="식물성","Y","N") | P9: N | Q9: =IF(AND(J9="취약",I9<>"있음",OR(M9="없음",M9="미상")),"Y","N") | R9: N | S9: =IF(NOT(ISNUMBER(D9)),0,IF(D9>=300,20,IF(D9>=200,15,IF(D9>=100,10,5))))+IF(NOT(ISNUMBER(E9)),0,IF(E9>=60,10,IF(E9>=40,6,3)))+IFERROR(VLOOKUP(F9,기준!$B$4:$C$7,2,FALSE),0) | T9: =IFERROR(VLOOKUP(I9,기준!$B$24:$C$26,2,FALSE),0)+IFERROR(VLOOKUP(J9,기준!$B$29:$C$32,2,FALSE),0)+IFERROR(VLOOKUP(K9,기준!$B$35:$C$41,2,FALSE),0) | U9: =IFERROR(VLOOKUP(G9,기준!$B$10:$C$13,2,FALSE),0)+IFERROR(VLOOKUP(H9,기준!$B$16:$C$21,2,FALSE),0) | V9: =IFERROR(VLOOKUP(L9,기준!$B$44:$C$46,2,FALSE),0)+IFERROR(VLOOKUP(M9,기준!$B$49:$C$52,2,FALSE),0)+IFERROR(VLOOKUP(N9,기준!$B$55:$C$58,2,FALSE),0) | W9: =SUM(S9:V9) | X9: =MIN(IF(O9="Y",20,100),IF(P9="Y",40,100),IF(Q9="Y",50,100),IF(R9="Y",40,100)) | Y9: =MIN(W9,X9) | Z9: =RANK(Y9,$Y$2:$Y$34,0) | AA9: 미상 | AB9: 미정 | AC9: =(IF(ISNUMBER(D9),1,0)+IF(ISNUMBER(E9),1,0)+IF(AND(F9<>"미상",F9<>""),1,0)+IF(AND(G9<>"미상",G9<>""),1,0)+IF(AND(H9<>"미상",H9<>""),1,0)+IF(AND(I9<>"미상",I9<>""),1,0)+IF(AND(J9<>"미상",J9<>""),1,0)+IF(AND(K9<>"미상",K9<>""),1,0)+IF(AND(L9<>"미상",L9<>""),1,0)+IF(AND(M9<>"미상",M9<>""),1,0)+IF(AND(N9<>"미상",N9<>""),1,0))&"/11" | AD9: 표시 500mg(오일 추정)·EPA+DHA 미상
A10: 9 | B10: 아베텍 오메가3벳 | C10: 펫·액상 | F10: 미상 | G10: 미상 | H10: 일반어 | I10: 있음 | J10: 미상 | K10: 펌프액상 | L10: 미상 | M10: 미상 | N10: 일부 | O10: =IF(H10="식물성","Y","N") | P10: N | Q10: =IF(AND(J10="취약",I10<>"있음",OR(M10="없음",M10="미상")),"Y","N") | R10: N | S10: =IF(NOT(ISNUMBER(D10)),0,IF(D10>=300,20,IF(D10>=200,15,IF(D10>=100,10,5))))+IF(NOT(ISNUMBER(E10)),0,IF(E10>=60,10,IF(E10>=40,6,3)))+IFERROR(VLOOKUP(F10,기준!$B$4:$C$7,2,FALSE),0) | T10: =IFERROR(VLOOKUP(I10,기준!$B$24:$C$26,2,FALSE),0)+IFERROR(VLOOKUP(J10,기준!$B$29:$C$32,2,FALSE),0)+IFERROR(VLOOKUP(K10,기준!$B$35:$C$41,2,FALSE),0) | U10: =IFERROR(VLOOKUP(G10,기준!$B$10:$C$13,2,FALSE),0)+IFERROR(VLOOKUP(H10,기준!$B$16:$C$21,2,FALSE),0) | V10: =IFERROR(VLOOKUP(L10,기준!$B$44:$C$46,2,FALSE),0)+IFERROR(VLOOKUP(M10,기준!$B$49:$C$52,2,FALSE),0)+IFERROR(VLOOKUP(N10,기준!$B$55:$C$58,2,FALSE),0) | W10: =SUM(S10:V10) | X10: =MIN(IF(O10="Y",20,100),IF(P10="Y",40,100),IF(Q10="Y",50,100),IF(R10="Y",40,100)) | Y10: =MIN(W10,X10) | Z10: =RANK(Y10,$Y$2:$Y$34,0) | AA10: 라벨만 | AB10: 미정 | AC10: =(IF(ISNUMBER(D10),1,0)+IF(ISNUMBER(E10),1,0)+IF(AND(F10<>"미상",F10<>""),1,0)+IF(AND(G10<>"미상",G10<>""),1,0)+IF(AND(H10<>"미상",H10<>""),1,0)+IF(AND(I10<>"미상",I10<>""),1,0)+IF(AND(J10<>"미상",J10<>""),1,0)+IF(AND(K10<>"미상",K10<>""),1,0)+IF(AND(L10<>"미상",L10<>""),1,0)+IF(AND(M10<>"미상",M10<>""),1,0)+IF(AND(N10<>"미상",N10<>""),1,0))&"/11" | AD10: 아베텍 오메가3벳 125ml 액상·남태평양/남극해 청정해역 바다생선(고함량 DHA·EPA·동물성)·고순도 정제(수직계열화)·천연항산화제·원산지 region만 명시(원료사 일부)·EPA+DHA mg·순도·형태(rTG/TG) 공식사이트도 미공개 (공식 a-vetech.com/94?idx=165·easypet 확인 20260620)
A11: 10 | B11: 페스룸 타이니 오메가-3 | C11: 펫·캡슐 | D11: 40 | E11: 80 | F11: 명시 | G11: rTG | H11: 소형어 | I11: 있음 | J11: 보통 | K11: 캡슐 | L11: 있음 | M11: 미상 | N11: 명시 | O11: =IF(H11="식물성","Y","N") | P11: N | Q11: =IF(AND(J11="취약",I11<>"있음",OR(M11="없음",M11="미상")),"Y","N") | R11: N | S11: =IF(NOT(ISNUMBER(D11)),0,IF(D11>=300,20,IF(D11>=200,15,IF(D11>=100,10,5))))+IF(NOT(ISNUMBER(E11)),0,IF(E11>=60,10,IF(E11>=40,6,3)))+IFERROR(VLOOKUP(F11,기준!$B$4:$C$7,2,FALSE),0) | T11: =IFERROR(VLOOKUP(I11,기준!$B$24:$C$26,2,FALSE),0)+IFERROR(VLOOKUP(J11,기준!$B$29:$C$32,2,FALSE),0)+IFERROR(VLOOKUP(K11,기준!$B$35:$C$41,2,FALSE),0) | U11: =IFERROR(VLOOKUP(G11,기준!$B$10:$C$13,2,FALSE),0)+IFERROR(VLOOKUP(H11,기준!$B$16:$C$21,2,FALSE),0) | V11: =IFERROR(VLOOKUP(L11,기준!$B$44:$C$46,2,FALSE),0)+IFERROR(VLOOKUP(M11,기준!$B$49:$C$52,2,FALSE),0)+IFERROR(VLOOKUP(N11,기준!$B$55:$C$58,2,FALSE),0) | W11: =SUM(S11:V11) | X11: =MIN(IF(O11="Y",20,100),IF(P11="Y",40,100),IF(Q11="Y",50,100),IF(R11="Y",40,100)) | Y11: =MIN(W11,X11) | Z11: =RANK(Y11,$Y$2:$Y$34,0) | AA11: 라벨만 | AB11: 일반유지 | AC11: =(IF(ISNUMBER(D11),1,0)+IF(ISNUMBER(E11),1,0)+IF(AND(F11<>"미상",F11<>""),1,0)+IF(AND(G11<>"미상",G11<>""),1,0)+IF(AND(H11<>"미상",H11<>""),1,0)+IF(AND(I11<>"미상",I11<>""),1,0)+IF(AND(J11<>"미상",J11<>""),1,0)+IF(AND(K11<>"미상",K11<>""),1,0)+IF(AND(L11<>"미상",L11<>""),1,0)+IF(AND(M11<>"미상",M11<>""),1,0)+IF(AND(N11<>"미상",N11<>""),1,0))&"/11" | AD11: 페스룸 TINY 오메가3 50mg(소형견·고양이 추천 SKU)·1캡슐 50mg 중 EPA+DHA 40mg·순도80%·3세대 rTG·멸치/청어 소형어·비타민E 0.13mg·통포장·KD Pharma(독일) 원료·IFOS5★+GOED 인증원료·150캡슐(0.5cm)·100mg형은 EPA48+DHA32=80mg/블리스터개별 (pethroom product_no=702 자동수집+비전 20260620)
A12: 11 | B12: 룰루파마 오메가3 | C12: 펫 | F12: 미상 | G12: 미상 | H12: 미상 | I12: 미상 | J12: 미상 | K12: 미상 | L12: 미상 | M12: 미상 | N12: 미상 | O12: =IF(H12="식물성","Y","N") | P12: N | Q12: =IF(AND(J12="취약",I12<>"있음",OR(M12="없음",M12="미상")),"Y","N") | R12: N | S12: =IF(NOT(ISNUMBER(D12)),0,IF(D12>=300,20,IF(D12>=200,15,IF(D12>=100,10,5))))+IF(NOT(ISNUMBER(E12)),0,IF(E12>=60,10,IF(E12>=40,6,3)))+IFERROR(VLOOKUP(F12,기준!$B$4:$C$7,2,FALSE),0) | T12: =IFERROR(VLOOKUP(I12,기준!$B$24:$C$26,2,FALSE),0)+IFERROR(VLOOKUP(J12,기준!$B$29:$C$32,2,FALSE),0)+IFERROR(VLOOKUP(K12,기준!$B$35:$C$41,2,FALSE),0) | U12: =IFERROR(VLOOKUP(G12,기준!$B$10:$C$13,2,FALSE),0)+IFERROR(VLOOKUP(H12,기준!$B$16:$C$21,2,FALSE),0) | V12: =IFERROR(VLOOKUP(L12,기준!$B$44:$C$46,2,FALSE),0)+IFERROR(VLOOKUP(M12,기준!$B$49:$C$52,2,FALSE),0)+IFERROR(VLOOKUP(N12,기준!$B$55:$C$58,2,FALSE),0) | W12: =SUM(S12:V12) | X12: =MIN(IF(O12="Y",20,100),IF(P12="Y",40,100),IF(Q12="Y",50,100),IF(R12="Y",40,100)) | Y12: =MIN(W12,X12) | Z12: =RANK(Y12,$Y$2:$Y$34,0) | AA12: 미상 | AB12: 미정 | AC12: =(IF(ISNUMBER(D12),1,0)+IF(ISNUMBER(E12),1,0)+IF(AND(F12<>"미상",F12<>""),1,0)+IF(AND(G12<>"미상",G12<>""),1,0)+IF(AND(H12<>"미상",H12<>""),1,0)+IF(AND(I12<>"미상",I12<>""),1,0)+IF(AND(J12<>"미상",J12<>""),1,0)+IF(AND(K12<>"미상",K12<>""),1,0)+IF(AND(L12<>"미상",L12<>""),1,0)+IF(AND(M12<>"미상",M12<>""),1,0)+IF(AND(N12<>"미상",N12<>""),1,0))&"/11" | AD12: 스펙 수집중
A13: 12 | B13: 씽크라이크펫 오메가3 | C13: 펫 | F13: 미상 | G13: 미상 | H13: 미상 | I13: 미상 | J13: 미상 | K13: 미상 | L13: 미상 | M13: 미상 | N13: 미상 | O13: =IF(H13="식물성","Y","N") | P13: N | Q13: =IF(AND(J13="취약",I13<>"있음",OR(M13="없음",M13="미상")),"Y","N") | R13: N | S13: =IF(NOT(ISNUMBER(D13)),0,IF(D13>=300,20,IF(D13>=200,15,IF(D13>=100,10,5))))+IF(NOT(ISNUMBER(E13)),0,IF(E13>=60,10,IF(E13>=40,6,3)))+IFERROR(VLOOKUP(F13,기준!$B$4:$C$7,2,FALSE),0) | T13: =IFERROR(VLOOKUP(I13,기준!$B$24:$C$26,2,FALSE),0)+IFERROR(VLOOKUP(J13,기준!$B$29:$C$32,2,FALSE),0)+IFERROR(VLOOKUP(K13,기준!$B$35:$C$41,2,FALSE),0) | U13: =IFERROR(VLOOKUP(G13,기준!$B$10:$C$13,2,FALSE),0)+IFERROR(VLOOKUP(H13,기준!$B$16:$C$21,2,FALSE),0) | V13: =IFERROR(VLOOKUP(L13,기준!$B$44:$C$46,2,FALSE),0)+IFERROR(VLOOKUP(M13,기준!$B$49:$C$52,2,FALSE),0)+IFERROR(VLOOKUP(N13,기준!$B$55:$C$58,2,FALSE),0) | W13: =SUM(S13:V13) | X13: =MIN(IF(O13="Y",20,100),IF(P13="Y",40,100),IF(Q13="Y",50,100),IF(R13="Y",40,100)) | Y13: =MIN(W13,X13) | Z13: =RANK(Y13,$Y$2:$Y$34,0) | AA13: 미상 | AB13: 미정 | AC13: =(IF(ISNUMBER(D13),1,0)+IF(ISNUMBER(E13),1,0)+IF(AND(F13<>"미상",F13<>""),1,0)+IF(AND(G13<>"미상",G13<>""),1,0)+IF(AND(H13<>"미상",H13<>""),1,0)+IF(AND(I13<>"미상",I13<>""),1,0)+IF(AND(J13<>"미상",J13<>""),1,0)+IF(AND(K13<>"미상",K13<>""),1,0)+IF(AND(L13<>"미상",L13<>""),1,0)+IF(AND(M13<>"미상",M13<>""),1,0)+IF(AND(N13<>"미상",N13<>""),1,0))&"/11" | AD13: 스펙 수집중
A14: 13 | B14: 이퀄 스틱 오메가3 | C14: 펫·스틱 | D14: 560 | F14: 일부 | G14: rTG | H14: 미상 | I14: 있음 | J14: 우수 | K14: 스틱 | L14: 미상 | M14: 미상 | N14: 미상 | O14: =IF(H14="식물성","Y","N") | P14: N | Q14: =IF(AND(J14="취약",I14<>"있음",OR(M14="없음",M14="미상")),"Y","N") | R14: N | S14: =IF(NOT(ISNUMBER(D14)),0,IF(D14>=300,20,IF(D14>=200,15,IF(D14>=100,10,5))))+IF(NOT(ISNUMBER(E14)),0,IF(E14>=60,10,IF(E14>=40,6,3)))+IFERROR(VLOOKUP(F14,기준!$B$4:$C$7,2,FALSE),0) | T14: =IFERROR(VLOOKUP(I14,기준!$B$24:$C$26,2,FALSE),0)+IFERROR(VLOOKUP(J14,기준!$B$29:$C$32,2,FALSE),0)+IFERROR(VLOOKUP(K14,기준!$B$35:$C$41,2,FALSE),0) | U14: =IFERROR(VLOOKUP(G14,기준!$B$10:$C$13,2,FALSE),0)+IFERROR(VLOOKUP(H14,기준!$B$16:$C$21,2,FALSE),0) | V14: =IFERROR(VLOOKUP(L14,기준!$B$44:$C$46,2,FALSE),0)+IFERROR(VLOOKUP(M14,기준!$B$49:$C$52,2,FALSE),0)+IFERROR(VLOOKUP(N14,기준!$B$55:$C$58,2,FALSE),0) | W14: =SUM(S14:V14) | X14: =MIN(IF(O14="Y",20,100),IF(P14="Y",40,100),IF(Q14="Y",50,100),IF(R14="Y",40,100)) | Y14: =MIN(W14,X14) | Z14: =RANK(Y14,$Y$2:$Y$34,0) | AA14: 라벨만 | AB14: 미정 | AC14: =(IF(ISNUMBER(D14),1,0)+IF(ISNUMBER(E14),1,0)+IF(AND(F14<>"미상",F14<>""),1,0)+IF(AND(G14<>"미상",G14<>""),1,0)+IF(AND(H14<>"미상",H14<>""),1,0)+IF(AND(I14<>"미상",I14<>""),1,0)+IF(AND(J14<>"미상",J14<>""),1,0)+IF(AND(K14<>"미상",K14<>""),1,0)+IF(AND(L14<>"미상",L14<>""),1,0)+IF(AND(M14<>"미상",M14<>""),1,0)+IF(AND(N14<>"미상",N14<>""),1,0))&"/11" | AD14: EPA+DHA 560mg/스틱(라벨 명시·고함량)·rTG·정제어유(어종 미표기)·천연토코페롤(항산화)·멸균 레토르트 개별스틱 공기차단포장·원료 정제수/타피오카전분/치커리/정제어유/가쓰오엑기스 (equalpet.store/product/50 자동수집+비전확인 20260620)
A15: 14 | B15: 펫생각 오메가3플러스 | C15: 펫·병원채널 | F15: 미상 | G15: 미상 | H15: 미상 | I15: 미상 | J15: 미상 | K15: 미상 | L15: 미상 | M15: 미상 | N15: 미상 | O15: =IF(H15="식물성","Y","N") | P15: N | Q15: =IF(AND(J15="취약",I15<>"있음",OR(M15="없음",M15="미상")),"Y","N") | R15: N | S15: =IF(NOT(ISNUMBER(D15)),0,IF(D15>=300,20,IF(D15>=200,15,IF(D15>=100,10,5))))+IF(NOT(ISNUMBER(E15)),0,IF(E15>=60,10,IF(E15>=40,6,3)))+IFERROR(VLOOKUP(F15,기준!$B$4:$C$7,2,FALSE),0) | T15: =IFERROR(VLOOKUP(I15,기준!$B$24:$C$26,2,FALSE),0)+IFERROR(VLOOKUP(J15,기준!$B$29:$C$32,2,FALSE),0)+IFERROR(VLOOKUP(K15,기준!$B$35:$C$41,2,FALSE),0) | U15: =IFERROR(VLOOKUP(G15,기준!$B$10:$C$13,2,FALSE),0)+IFERROR(VLOOKUP(H15,기준!$B$16:$C$21,2,FALSE),0) | V15: =IFERROR(VLOOKUP(L15,기준!$B$44:$C$46,2,FALSE),0)+IFERROR(VLOOKUP(M15,기준!$B$49:$C$52,2,FALSE),0)+IFERROR(VLOOKUP(N15,기준!$B$55:$C$58,2,FALSE),0) | W15: =SUM(S15:V15) | X15: =MIN(IF(O15="Y",20,100),IF(P15="Y",40,100),IF(Q15="Y",50,100),IF(R15="Y",40,100)) | Y15: =MIN(W15,X15) | Z15: =RANK(Y15,$Y$2:$Y$34,0) | AA15: 라벨만 | AB15: 미정 | AC15: =(IF(ISNUMBER(D15),1,0)+IF(ISNUMBER(E15),1,0)+IF(AND(F15<>"미상",F15<>""),1,0)+IF(AND(G15<>"미상",G15<>""),1,0)+IF(AND(H15<>"미상",H15<>""),1,0)+IF(AND(I15<>"미상",I15<>""),1,0)+IF(AND(J15<>"미상",J15<>""),1,0)+IF(AND(K15<>"미상",K15<>""),1,0)+IF(AND(L15<>"미상",L15<>""),1,0)+IF(AND(M15<>"미상",M15<>""),1,0)+IF(AND(N15<>"미상",N15<>""),1,0))&"/11" | AD15: 동물병원협회 추천 (비타트라)
A16: 15 | B16: 펫생각 데일리케얼 오메가3 미니 | C16: 펫 | D16: 128 | E16: 80 | F16: 일부 | G16: rTG | H16: 소형어 | I16: 있음 | J16: 우수 | K16: 캡슐 | L16: 있음 | M16: 공개 | N16: 명시 | O16: =IF(H16="식물성","Y","N") | P16: N | Q16: =IF(AND(J16="취약",I16<>"있음",OR(M16="없음",M16="미상")),"Y","N") | R16: N | S16: =IF(NOT(ISNUMBER(D16)),0,IF(D16>=300,20,IF(D16>=200,15,IF(D16>=100,10,5))))+IF(NOT(ISNUMBER(E16)),0,IF(E16>=60,10,IF(E16>=40,6,3)))+IFERROR(VLOOKUP(F16,기준!$B$4:$C$7,2,FALSE),0) | T16: =IFERROR(VLOOKUP(I16,기준!$B$24:$C$26,2,FALSE),0)+IFERROR(VLOOKUP(J16,기준!$B$29:$C$32,2,FALSE),0)+IFERROR(VLOOKUP(K16,기준!$B$35:$C$41,2,FALSE),0) | U16: =IFERROR(VLOOKUP(G16,기준!$B$10:$C$13,2,FALSE),0)+IFERROR(VLOOKUP(H16,기준!$B$16:$C$21,2,FALSE),0) | V16: =IFERROR(VLOOKUP(L16,기준!$B$44:$C$46,2,FALSE),0)+IFERROR(VLOOKUP(M16,기준!$B$49:$C$52,2,FALSE),0)+IFERROR(VLOOKUP(N16,기준!$B$55:$C$58,2,FALSE),0) | W16: =SUM(S16:V16) | X16: =MIN(IF(O16="Y",20,100),IF(P16="Y",40,100),IF(Q16="Y",50,100),IF(R16="Y",40,100)) | Y16: =MIN(W16,X16) | Z16: =RANK(Y16,$Y$2:$Y$34,0) | AA16: 공개·검증 | AB16: 일반유지 | AC16: =(IF(ISNUMBER(D16),1,0)+IF(ISNUMBER(E16),1,0)+IF(AND(F16<>"미상",F16<>""),1,0)+IF(AND(G16<>"미상",G16<>""),1,0)+IF(AND(H16<>"미상",H16<>""),1,0)+IF(AND(I16<>"미상",I16<>""),1,0)+IF(AND(J16<>"미상",J16<>""),1,0)+IF(AND(K16<>"미상",K16<>""),1,0)+IF(AND(L16<>"미상",L16<>""),1,0)+IF(AND(M16<>"미상",M16<>""),1,0)+IF(AND(N16<>"미상",N16<>""),1,0))&"/11" | AD16: 데일리케얼 슈퍼리얼 알티지(180캡슐 SKU 기준)·1캡슐 EPA+DHA 128mg·순도80%이상·Real rTG·정제어유 소형어·d-토코페롤(비타민E)·PTP개별포장 산패4중방어·KD파마(독일) 원료+완제품 IFOS5★·TOTOX/중금속 검사공개·연질캡슐 (fitpetmall goods/1000033651 자동수집+OCR 20260620)
A17: 16 | B17: 아이슬란딕 헤링 오메가3 | C17: 펫·액상 | D17: 147 | E17: 15 | F17: 명시 | G17: TG | H17: 소형어 | I17: 미상 | J17: 보통 | K17: 펌프액상 | L17: 미상 | M17: 공개 | N17: 명시 | O17: =IF(H17="식물성","Y","N") | P17: N | Q17: =IF(AND(J17="취약",I17<>"있음",OR(M17="없음",M17="미상")),"Y","N") | R17: N | S17: =IF(NOT(ISNUMBER(D17)),0,IF(D17>=300,20,IF(D17>=200,15,IF(D17>=100,10,5))))+IF(NOT(ISNUMBER(E17)),0,IF(E17>=60,10,IF(E17>=40,6,3)))+IFERROR(VLOOKUP(F17,기준!$B$4:$C$7,2,FALSE),0) | T17: =IFERROR(VLOOKUP(I17,기준!$B$24:$C$26,2,FALSE),0)+IFERROR(VLOOKUP(J17,기준!$B$29:$C$32,2,FALSE),0)+IFERROR(VLOOKUP(K17,기준!$B$35:$C$41,2,FALSE),0) | U17: =IFERROR(VLOOKUP(G17,기준!$B$10:$C$13,2,FALSE),0)+IFERROR(VLOOKUP(H17,기준!$B$16:$C$21,2,FALSE),0) | V17: =IFERROR(VLOOKUP(L17,기준!$B$44:$C$46,2,FALSE),0)+IFERROR(VLOOKUP(M17,기준!$B$49:$C$52,2,FALSE),0)+IFERROR(VLOOKUP(N17,기준!$B$55:$C$58,2,FALSE),0) | W17: =SUM(S17:V17) | X17: =MIN(IF(O17="Y",20,100),IF(P17="Y",40,100),IF(Q17="Y",50,100),IF(R17="Y",40,100)) | Y17: =MIN(W17,X17) | Z17: =RANK(Y17,$Y$2:$Y$34,0) | AA17: 공개·검증 | AB17: 일반유지 | AC17: =(IF(ISNUMBER(D17),1,0)+IF(ISNUMBER(E17),1,0)+IF(AND(F17<>"미상",F17<>""),1,0)+IF(AND(G17<>"미상",G17<>""),1,0)+IF(AND(H17<>"미상",H17<>""),1,0)+IF(AND(I17<>"미상",I17<>""),1,0)+IF(AND(J17<>"미상",J17<>""),1,0)+IF(AND(K17<>"미상",K17<>""),1,0)+IF(AND(L17<>"미상",L17<>""),1,0)+IF(AND(M17<>"미상",M17<>""),1,0)+IF(AND(N17<>"미상",N17<>""),1,0))&"/11" | AD17: 카이쿠라 청어100% 아이슬란드산 자연어유(TG)·성분표 per1g Total오메가3 199mg·DHA79+EPA70=147mg·DPA10mg·VitA/D ND·순도≈15%(147/1000)·사료검정 산가0.01(COA공개)·MSC인증·1펌프≈1ml·250ml (kaikoora.com/product/13 자동수집+비전확인 20260620)
A18: 17 | B18: 바이오펫츠 펫메가3 | C18: 펫·액상 | D18: 84 | F18: 일부 | G18: TG | H18: 일반어 | I18: 미상 | J18: 우수 | K18: 펌프액상 | L18: 미상 | M18: 일부 | N18: 명시 | O18: =IF(H18="식물성","Y","N") | P18: N | Q18: =IF(AND(J18="취약",I18<>"있음",OR(M18="없음",M18="미상")),"Y","N") | R18: N | S18: =IF(NOT(ISNUMBER(D18)),0,IF(D18>=300,20,IF(D18>=200,15,IF(D18>=100,10,5))))+IF(NOT(ISNUMBER(E18)),0,IF(E18>=60,10,IF(E18>=40,6,3)))+IFERROR(VLOOKUP(F18,기준!$B$4:$C$7,2,FALSE),0) | T18: =IFERROR(VLOOKUP(I18,기준!$B$24:$C$26,2,FALSE),0)+IFERROR(VLOOKUP(J18,기준!$B$29:$C$32,2,FALSE),0)+IFERROR(VLOOKUP(K18,기준!$B$35:$C$41,2,FALSE),0) | U18: =IFERROR(VLOOKUP(G18,기준!$B$10:$C$13,2,FALSE),0)+IFERROR(VLOOKUP(H18,기준!$B$16:$C$21,2,FALSE),0) | V18: =IFERROR(VLOOKUP(L18,기준!$B$44:$C$46,2,FALSE),0)+IFERROR(VLOOKUP(M18,기준!$B$49:$C$52,2,FALSE),0)+IFERROR(VLOOKUP(N18,기준!$B$55:$C$58,2,FALSE),0) | W18: =SUM(S18:V18) | X18: =MIN(IF(O18="Y",20,100),IF(P18="Y",40,100),IF(Q18="Y",50,100),IF(R18="Y",40,100)) | Y18: =MIN(W18,X18) | Z18: =RANK(Y18,$Y$2:$Y$34,0) | AA18: 라벨만 | AB18: 일반유지 | AC18: =(IF(ISNUMBER(D18),1,0)+IF(ISNUMBER(E18),1,0)+IF(AND(F18<>"미상",F18<>""),1,0)+IF(AND(G18<>"미상",G18<>""),1,0)+IF(AND(H18<>"미상",H18<>""),1,0)+IF(AND(I18<>"미상",I18<>""),1,0)+IF(AND(J18<>"미상",J18<>""),1,0)+IF(AND(K18<>"미상",K18<>""),1,0)+IF(AND(L18<>"미상",L18<>""),1,0)+IF(AND(M18<>"미상",M18<>""),1,0)+IF(AND(N18<>"미상",N18<>""),1,0))&"/11" | AD18: 바이오펫츠 펫메가3 150ml·1ml당 EPA+DHA 64~103mg(중간값 84)·연어오일99%(원육 노르웨이)·자연 비농축(TG)·공기차단 특허용기(특허 20-0470695)·비타민 1% 첨가·산가 2.5 공개(COA 일부)·per회분 mg 미상 (fitpetmall goods/1000037912 자동수집+OCR 20260620)
A19: 18 | B19: 브릴리언트 연어오일 1000ml | C19: 펫·액상 | D19: 50 | E19: 5 | F19: 명시 | G19: TG | H19: 일반어 | I19: 있음 | J19: 보통 | K19: 대용량액상 | L19: 미상 | M19: 공개 | N19: 명시 | O19: =IF(H19="식물성","Y","N") | P19: N | Q19: =IF(AND(J19="취약",I19<>"있음",OR(M19="없음",M19="미상")),"Y","N") | R19: N | S19: =IF(NOT(ISNUMBER(D19)),0,IF(D19>=300,20,IF(D19>=200,15,IF(D19>=100,10,5))))+IF(NOT(ISNUMBER(E19)),0,IF(E19>=60,10,IF(E19>=40,6,3)))+IFERROR(VLOOKUP(F19,기준!$B$4:$C$7,2,FALSE),0) | T19: =IFERROR(VLOOKUP(I19,기준!$B$24:$C$26,2,FALSE),0)+IFERROR(VLOOKUP(J19,기준!$B$29:$C$32,2,FALSE),0)+IFERROR(VLOOKUP(K19,기준!$B$35:$C$41,2,FALSE),0) | U19: =IFERROR(VLOOKUP(G19,기준!$B$10:$C$13,2,FALSE),0)+IFERROR(VLOOKUP(H19,기준!$B$16:$C$21,2,FALSE),0) | V19: =IFERROR(VLOOKUP(L19,기준!$B$44:$C$46,2,FALSE),0)+IFERROR(VLOOKUP(M19,기준!$B$49:$C$52,2,FALSE),0)+IFERROR(VLOOKUP(N19,기준!$B$55:$C$58,2,FALSE),0) | W19: =SUM(S19:V19) | X19: =MIN(IF(O19="Y",20,100),IF(P19="Y",40,100),IF(Q19="Y",50,100),IF(R19="Y",40,100)) | Y19: =MIN(W19,X19) | Z19: =RANK(Y19,$Y$2:$Y$34,0) | AA19: 공개·검증 | AB19: 일반유지 | AC19: =(IF(ISNUMBER(D19),1,0)+IF(ISNUMBER(E19),1,0)+IF(AND(F19<>"미상",F19<>""),1,0)+IF(AND(G19<>"미상",G19<>""),1,0)+IF(AND(H19<>"미상",H19<>""),1,0)+IF(AND(I19<>"미상",I19<>""),1,0)+IF(AND(J19<>"미상",J19<>""),1,0)+IF(AND(K19<>"미상",K19<>""),1,0)+IF(AND(L19<>"미상",L19<>""),1,0)+IF(AND(M19<>"미상",M19<>""),1,0)+IF(AND(N19<>"미상",N19<>""),1,0))&"/11" | AD19: 브릴리언트 연어오일 CoA(페오펫 300ml 동일오일)·EPA≥20+DHA≥30=≥50mg/g·DPA≥10·Total오메가3≥140mg/g·Fat≥99%(순도≈5%)·노르웨이 연어 자연유(TG)·Astaxanthin>6µg/g(천연항산화)·Peroxide≤12/Anisidine≤8/중금속<0.1/PCB·다이옥신 분기검사(COA공개)·차단펌프(공기차단)·Friend of the Sea (shop.peopet.co.kr/goods/36686 비전확인 20260620)
A20: 19 | B20: 살모펫 노르웨이 연어오일 | C20: 펫·액상 | F20: 미상 | G20: TG | H20: 일반어 | I20: 미상 | J20: 미상 | K20: 펌프액상 | L20: 미상 | M20: 미상 | N20: 명시 | O20: =IF(H20="식물성","Y","N") | P20: N | Q20: =IF(AND(J20="취약",I20<>"있음",OR(M20="없음",M20="미상")),"Y","N") | R20: N | S20: =IF(NOT(ISNUMBER(D20)),0,IF(D20>=300,20,IF(D20>=200,15,IF(D20>=100,10,5))))+IF(NOT(ISNUMBER(E20)),0,IF(E20>=60,10,IF(E20>=40,6,3)))+IFERROR(VLOOKUP(F20,기준!$B$4:$C$7,2,FALSE),0) | T20: =IFERROR(VLOOKUP(I20,기준!$B$24:$C$26,2,FALSE),0)+IFERROR(VLOOKUP(J20,기준!$B$29:$C$32,2,FALSE),0)+IFERROR(VLOOKUP(K20,기준!$B$35:$C$41,2,FALSE),0) | U20: =IFERROR(VLOOKUP(G20,기준!$B$10:$C$13,2,FALSE),0)+IFERROR(VLOOKUP(H20,기준!$B$16:$C$21,2,FALSE),0) | V20: =IFERROR(VLOOKUP(L20,기준!$B$44:$C$46,2,FALSE),0)+IFERROR(VLOOKUP(M20,기준!$B$49:$C$52,2,FALSE),0)+IFERROR(VLOOKUP(N20,기준!$B$55:$C$58,2,FALSE),0) | W20: =SUM(S20:V20) | X20: =MIN(IF(O20="Y",20,100),IF(P20="Y",40,100),IF(Q20="Y",50,100),IF(R20="Y",40,100)) | Y20: =MIN(W20,X20) | Z20: =RANK(Y20,$Y$2:$Y$34,0) | AA20: 라벨만 | AB20: 미정 | AC20: =(IF(ISNUMBER(D20),1,0)+IF(ISNUMBER(E20),1,0)+IF(AND(F20<>"미상",F20<>""),1,0)+IF(AND(G20<>"미상",G20<>""),1,0)+IF(AND(H20<>"미상",H20<>""),1,0)+IF(AND(I20<>"미상",I20<>""),1,0)+IF(AND(J20<>"미상",J20<>""),1,0)+IF(AND(K20<>"미상",K20<>""),1,0)+IF(AND(L20<>"미상",L20<>""),1,0)+IF(AND(M20<>"미상",M20<>""),1,0)+IF(AND(N20<>"미상",N20<>""),1,0))&"/11" | AD20: Salmo Pet 노르웨이산 연어오일(NORGE 원산지 명시)·자연어유(TG)·연어 단일·5kg미만 1펌프~·DHA·EPA 함유 표기만·per펌프 EPA+DHA mg 미공개 (fitpetmall goods/1000024792 자동수집+비전 20260620)
A21: 20 | B21: 뉴트리벳 오메가3 | C21: 펫·액상 | F21: 미상 | G21: 미상 | H21: 일반어 | I21: 미상 | J21: 미상 | K21: 펌프액상 | L21: 미상 | M21: 미상 | N21: 미상 | O21: =IF(H21="식물성","Y","N") | P21: N | Q21: =IF(AND(J21="취약",I21<>"있음",OR(M21="없음",M21="미상")),"Y","N") | R21: N | S21: =IF(NOT(ISNUMBER(D21)),0,IF(D21>=300,20,IF(D21>=200,15,IF(D21>=100,10,5))))+IF(NOT(ISNUMBER(E21)),0,IF(E21>=60,10,IF(E21>=40,6,3)))+IFERROR(VLOOKUP(F21,기준!$B$4:$C$7,2,FALSE),0) | T21: =IFERROR(VLOOKUP(I21,기준!$B$24:$C$26,2,FALSE),0)+IFERROR(VLOOKUP(J21,기준!$B$29:$C$32,2,FALSE),0)+IFERROR(VLOOKUP(K21,기준!$B$35:$C$41,2,FALSE),0) | U21: =IFERROR(VLOOKUP(G21,기준!$B$10:$C$13,2,FALSE),0)+IFERROR(VLOOKUP(H21,기준!$B$16:$C$21,2,FALSE),0) | V21: =IFERROR(VLOOKUP(L21,기준!$B$44:$C$46,2,FALSE),0)+IFERROR(VLOOKUP(M21,기준!$B$49:$C$52,2,FALSE),0)+IFERROR(VLOOKUP(N21,기준!$B$55:$C$58,2,FALSE),0) | W21: =SUM(S21:V21) | X21: =MIN(IF(O21="Y",20,100),IF(P21="Y",40,100),IF(Q21="Y",50,100),IF(R21="Y",40,100)) | Y21: =MIN(W21,X21) | Z21: =RANK(Y21,$Y$2:$Y$34,0) | AA21: 라벨만 | AB21: 미정 | AC21: =(IF(ISNUMBER(D21),1,0)+IF(ISNUMBER(E21),1,0)+IF(AND(F21<>"미상",F21<>""),1,0)+IF(AND(G21<>"미상",G21<>""),1,0)+IF(AND(H21<>"미상",H21<>""),1,0)+IF(AND(I21<>"미상",I21<>""),1,0)+IF(AND(J21<>"미상",J21<>""),1,0)+IF(AND(K21<>"미상",K21<>""),1,0)+IF(AND(L21<>"미상",L21<>""),1,0)+IF(AND(M21<>"미상",M21<>""),1,0)+IF(AND(N21<>"미상",N21<>""),1,0))&"/11" | AD21: 연어+폴락(대구과 어체유, 간유 아님)→비타민A/D 상한 부적용·국내 판매처 없음(2026-06 확인)·단종 추정으로 추가 수집 불가 (구 핏펫)
A22: 21 | B22: 오메가3 플러스펫 프리미엄 | C22: 펫·액상 | F22: 미상 | G22: TG | H22: 해양포유류 | I22: 미상 | J22: 미상 | K22: 펌프액상 | L22: 미상 | M22: 미상 | N22: 명시 | O22: =IF(H22="식물성","Y","N") | P22: N | Q22: =IF(AND(J22="취약",I22<>"있음",OR(M22="없음",M22="미상")),"Y","N") | R22: N | S22: =IF(NOT(ISNUMBER(D22)),0,IF(D22>=300,20,IF(D22>=200,15,IF(D22>=100,10,5))))+IF(NOT(ISNUMBER(E22)),0,IF(E22>=60,10,IF(E22>=40,6,3)))+IFERROR(VLOOKUP(F22,기준!$B$4:$C$7,2,FALSE),0) | T22: =IFERROR(VLOOKUP(I22,기준!$B$24:$C$26,2,FALSE),0)+IFERROR(VLOOKUP(J22,기준!$B$29:$C$32,2,FALSE),0)+IFERROR(VLOOKUP(K22,기준!$B$35:$C$41,2,FALSE),0) | U22: =IFERROR(VLOOKUP(G22,기준!$B$10:$C$13,2,FALSE),0)+IFERROR(VLOOKUP(H22,기준!$B$16:$C$21,2,FALSE),0) | V22: =IFERROR(VLOOKUP(L22,기준!$B$44:$C$46,2,FALSE),0)+IFERROR(VLOOKUP(M22,기준!$B$49:$C$52,2,FALSE),0)+IFERROR(VLOOKUP(N22,기준!$B$55:$C$58,2,FALSE),0) | W22: =SUM(S22:V22) | X22: =MIN(IF(O22="Y",20,100),IF(P22="Y",40,100),IF(Q22="Y",50,100),IF(R22="Y",40,100)) | Y22: =MIN(W22,X22) | Z22: =RANK(Y22,$Y$2:$Y$34,0) | AA22: 라벨만 | AB22: 미정 | AC22: =(IF(ISNUMBER(D22),1,0)+IF(ISNUMBER(E22),1,0)+IF(AND(F22<>"미상",F22<>""),1,0)+IF(AND(G22<>"미상",G22<>""),1,0)+IF(AND(H22<>"미상",H22<>""),1,0)+IF(AND(I22<>"미상",I22<>""),1,0)+IF(AND(J22<>"미상",J22<>""),1,0)+IF(AND(K22<>"미상",K22<>""),1,0)+IF(AND(L22<>"미상",L22<>""),1,0)+IF(AND(M22<>"미상",M22<>""),1,0)+IF(AND(N22<>"미상",N22<>""),1,0))&"/11" | AD22: 오메가3 플러스펫 캐나다 물개오일 140ml+루테인·해양 포유류 오일(해양성·EPA/DHA/DPA 공급
A23: 22 | B23: 닥터뮨 식물성 오메가3 | C23: 펫·식물성 | E23: 64.5 | F23: 미상 | G23: 미상 | H23: 조류 | I23: 미상 | J23: 미상 | K23: 미상 | L23: 미상 | M23: 미상 | N23: 미상 | O23: =IF(H23="식물성","Y","N") | P23: N | Q23: =IF(AND(J23="취약",I23<>"있음",OR(M23="없음",M23="미상")),"Y","N") | R23: N | S23: =IF(NOT(ISNUMBER(D23)),0,IF(D23>=300,20,IF(D23>=200,15,IF(D23>=100,10,5))))+IF(NOT(ISNUMBER(E23)),0,IF(E23>=60,10,IF(E23>=40,6,3)))+IFERROR(VLOOKUP(F23,기준!$B$4:$C$7,2,FALSE),0) | T23: =IFERROR(VLOOKUP(I23,기준!$B$24:$C$26,2,FALSE),0)+IFERROR(VLOOKUP(J23,기준!$B$29:$C$32,2,FALSE),0)+IFERROR(VLOOKUP(K23,기준!$B$35:$C$41,2,FALSE),0) | U23: =IFERROR(VLOOKUP(G23,기준!$B$10:$C$13,2,FALSE),0)+IFERROR(VLOOKUP(H23,기준!$B$16:$C$21,2,FALSE),0) | V23: =IFERROR(VLOOKUP(L23,기준!$B$44:$C$46,2,FALSE),0)+IFERROR(VLOOKUP(M23,기준!$B$49:$C$52,2,FALSE),0)+IFERROR(VLOOKUP(N23,기준!$B$55:$C$58,2,FALSE),0) | W23: =SUM(S23:V23) | X23: =MIN(IF(O23="Y",20,100),IF(P23="Y",40,100),IF(Q23="Y",50,100),IF(R23="Y",40,100)) | Y23: =MIN(W23,X23) | Z23: =RANK(Y23,$Y$2:$Y$34,0) | AA23: 라벨만 | AB23: DHA중심(조류) | AC23: =(IF(ISNUMBER(D23),1,0)+IF(ISNUMBER(E23),1,0)+IF(AND(F23<>"미상",F23<>""),1,0)+IF(AND(G23<>"미상",G23<>""),1,0)+IF(AND(H23<>"미상",H23<>""),1,0)+IF(AND(I23<>"미상",I23<>""),1,0)+IF(AND(J23<>"미상",J23<>""),1,0)+IF(AND(K23<>"미상",K23<>""),1,0)+IF(AND(L23<>"미상",L23<>""),1,0)+IF(AND(M23<>"미상",M23<>""),1,0)+IF(AND(N23<>"미상",N23<>""),1,0))&"/11" | AD23: 미세조류 추출 식물성→조류(정상·상한해제 확정)·1g당 EPA+DHA 645mg→순도64.5%·per캡슐mg 미상(이미지잠금) (drmune.com/etnews 20260210)
A24: 23 | B24: 뉴트리코어 펫 식물성 rTG | C24: 펫·식물성 | F24: 미상 | G24: rTG | H24: 조류 | I24: 미상 | J24: 미상 | K24: 미상 | L24: 미상 | M24: 미상 | N24: 미상 | O24: =IF(H24="식물성","Y","N") | P24: N | Q24: =IF(AND(J24="취약",I24<>"있음",OR(M24="없음",M24="미상")),"Y","N") | R24: N | S24: =IF(NOT(ISNUMBER(D24)),0,IF(D24>=300,20,IF(D24>=200,15,IF(D24>=100,10,5))))+IF(NOT(ISNUMBER(E24)),0,IF(E24>=60,10,IF(E24>=40,6,3)))+IFERROR(VLOOKUP(F24,기준!$B$4:$C$7,2,FALSE),0) | T24: =IFERROR(VLOOKUP(I24,기준!$B$24:$C$26,2,FALSE),0)+IFERROR(VLOOKUP(J24,기준!$B$29:$C$32,2,FALSE),0)+IFERROR(VLOOKUP(K24,기준!$B$35:$C$41,2,FALSE),0) | U24: =IFERROR(VLOOKUP(G24,기준!$B$10:$C$13,2,FALSE),0)+IFERROR(VLOOKUP(H24,기준!$B$16:$C$21,2,FALSE),0) | V24: =IFERROR(VLOOKUP(L24,기준!$B$44:$C$46,2,FALSE),0)+IFERROR(VLOOKUP(M24,기준!$B$49:$C$52,2,FALSE),0)+IFERROR(VLOOKUP(N24,기준!$B$55:$C$58,2,FALSE),0) | W24: =SUM(S24:V24) | X24: =MIN(IF(O24="Y",20,100),IF(P24="Y",40,100),IF(Q24="Y",50,100),IF(R24="Y",40,100)) | Y24: =MIN(W24,X24) | Z24: =RANK(Y24,$Y$2:$Y$34,0) | AA24: 라벨만 | AB24: DHA중심(조류) | AC24: =(IF(ISNUMBER(D24),1,0)+IF(ISNUMBER(E24),1,0)+IF(AND(F24<>"미상",F24<>""),1,0)+IF(AND(G24<>"미상",G24<>""),1,0)+IF(AND(H24<>"미상",H24<>""),1,0)+IF(AND(I24<>"미상",I24<>""),1,0)+IF(AND(J24<>"미상",J24<>""),1,0)+IF(AND(K24<>"미상",K24<>""),1,0)+IF(AND(L24<>"미상",L24<>""),1,0)+IF(AND(M24<>"미상",M24<>""),1,0)+IF(AND(N24<>"미상",N24<>""),1,0))&"/11" | AD24: 식물성 rTG=미세조류 DHA(EPA 거의 없음)·상한 부적용·DHA 편중·브랜드 식물성라인 순도~80%·공식몰(nutricore.co.kr) 로그인 게이트라 펫 SKU 스펙 직접확인 불가·확인된 건 사람용 하이퍼셀(EPA+DHA 900mg/일·미세조류 rTG)뿐 (소셜타임스·공식 goodsInnb 2608678 게이트)
A25: 24 | B25: klnix 클리닉스 MEGA-3A | C25: 병원·클리닉 | F25: 미상 | G25: 미상 | H25: 미상 | I25: 있음 | J25: 미상 | K25: 미상 | L25: 미상 | M25: 미상 | N25: 명시 | O25: =IF(H25="식물성","Y","N") | P25: N | Q25: =IF(AND(J25="취약",I25<>"있음",OR(M25="없음",M25="미상")),"Y","N") | R25: N | S25: =IF(NOT(ISNUMBER(D25)),0,IF(D25>=300,20,IF(D25>=200,15,IF(D25>=100,10,5))))+IF(NOT(ISNUMBER(E25)),0,IF(E25>=60,10,IF(E25>=40,6,3)))+IFERROR(VLOOKUP(F25,기준!$B$4:$C$7,2,FALSE),0) | T25: =IFERROR(VLOOKUP(I25,기준!$B$24:$C$26,2,FALSE),0)+IFERROR(VLOOKUP(J25,기준!$B$29:$C$32,2,FALSE),0)+IFERROR(VLOOKUP(K25,기준!$B$35:$C$41,2,FALSE),0) | U25: =IFERROR(VLOOKUP(G25,기준!$B$10:$C$13,2,FALSE),0)+IFERROR(VLOOKUP(H25,기준!$B$16:$C$21,2,FALSE),0) | V25: =IFERROR(VLOOKUP(L25,기준!$B$44:$C$46,2,FALSE),0)+IFERROR(VLOOKUP(M25,기준!$B$49:$C$52,2,FALSE),0)+IFERROR(VLOOKUP(N25,기준!$B$55:$C$58,2,FALSE),0) | W25: =SUM(S25:V25) | X25: =MIN(IF(O25="Y",20,100),IF(P25="Y",40,100),IF(Q25="Y",50,100),IF(R25="Y",40,100)) | Y25: =MIN(W25,X25) | Z25: =RANK(Y25,$Y$2:$Y$34,0) | AA25: 라벨만 | AB25: 미정 | AC25: =(IF(ISNUMBER(D25),1,0)+IF(ISNUMBER(E25),1,0)+IF(AND(F25<>"미상",F25<>""),1,0)+IF(AND(G25<>"미상",G25<>""),1,0)+IF(AND(H25<>"미상",H25<>""),1,0)+IF(AND(I25<>"미상",I25<>""),1,0)+IF(AND(J25<>"미상",J25<>""),1,0)+IF(AND(K25<>"미상",K25<>""),1,0)+IF(AND(L25<>"미상",L25<>""),1,0)+IF(AND(M25<>"미상",M25<>""),1,0)+IF(AND(N25<>"미상",N25<>""),1,0))&"/11" | AD25: 클리닉스 MEGA-3A 미세파우더(가루) 80g·제형토큰 없음(파우더)·생선오일분말(어종 미표기)·EPA/DHA/ALA 함유하나 per회분 mg·순도 미공개(한 스푼≈제품 700mg)·항산화 비타민E+천연알파토코페롤+로즈마리추출물·제조원 대성물산(원료사 명시)·24개월 산패안정성·성분등록 제55VVW0022 (petemart 2124 자동수집+비전 20260620)
A26: 25 | B26: venefit omega3 plus | C26: 병원·클리닉 | F26: 미상 | G26: 미상 | H26: 미상 | I26: 미상 | J26: 미상 | K26: 미상 | L26: 미상 | M26: 미상 | N26: 미상 | O26: =IF(H26="식물성","Y","N") | P26: N | Q26: =IF(AND(J26="취약",I26<>"있음",OR(M26="없음",M26="미상")),"Y","N") | R26: N | S26: =IF(NOT(ISNUMBER(D26)),0,IF(D26>=300,20,IF(D26>=200,15,IF(D26>=100,10,5))))+IF(NOT(ISNUMBER(E26)),0,IF(E26>=60,10,IF(E26>=40,6,3)))+IFERROR(VLOOKUP(F26,기준!$B$4:$C$7,2,FALSE),0) | T26: =IFERROR(VLOOKUP(I26,기준!$B$24:$C$26,2,FALSE),0)+IFERROR(VLOOKUP(J26,기준!$B$29:$C$32,2,FALSE),0)+IFERROR(VLOOKUP(K26,기준!$B$35:$C$41,2,FALSE),0) | U26: =IFERROR(VLOOKUP(G26,기준!$B$10:$C$13,2,FALSE),0)+IFERROR(VLOOKUP(H26,기준!$B$16:$C$21,2,FALSE),0) | V26: =IFERROR(VLOOKUP(L26,기준!$B$44:$C$46,2,FALSE),0)+IFERROR(VLOOKUP(M26,기준!$B$49:$C$52,2,FALSE),0)+IFERROR(VLOOKUP(N26,기준!$B$55:$C$58,2,FALSE),0) | W26: =SUM(S26:V26) | X26: =MIN(IF(O26="Y",20,100),IF(P26="Y",40,100),IF(Q26="Y",50,100),IF(R26="Y",40,100)) | Y26: =MIN(W26,X26) | Z26: =RANK(Y26,$Y$2:$Y$34,0) | AA26: 미상 | AB26: 미정 | AC26: =(IF(ISNUMBER(D26),1,0)+IF(ISNUMBER(E26),1,0)+IF(AND(F26<>"미상",F26<>""),1,0)+IF(AND(G26<>"미상",G26<>""),1,0)+IF(AND(H26<>"미상",H26<>""),1,0)+IF(AND(I26<>"미상",I26<>""),1,0)+IF(AND(J26<>"미상",J26<>""),1,0)+IF(AND(K26<>"미상",K26<>""),1,0)+IF(AND(L26<>"미상",L26<>""),1,0)+IF(AND(M26<>"미상",M26<>""),1,0)+IF(AND(N26<>"미상",N26<>""),1,0))&"/11" | AD26: 병원 납품·공개정보 적음·수집중
A27: 26 | B27: 스포츠리서치 트리플 스트렝스 | C27: 사람용 | D27: 937 | E27: 75 | F27: 명시 | G27: TG | H27: 소형어 | I27: 미상 | J27: 취약 | K27: 소프트젤 | L27: 있음 | M27: 일부 | N27: 명시 | O27: =IF(H27="식물성","Y","N") | P27: N | Q27: =IF(AND(J27="취약",I27<>"있음",OR(M27="없음",M27="미상")),"Y","N") | R27: N | S27: =IF(NOT(ISNUMBER(D27)),0,IF(D27>=300,20,IF(D27>=200,15,IF(D27>=100,10,5))))+IF(NOT(ISNUMBER(E27)),0,IF(E27>=60,10,IF(E27>=40,6,3)))+IFERROR(VLOOKUP(F27,기준!$B$4:$C$7,2,FALSE),0) | T27: =IFERROR(VLOOKUP(I27,기준!$B$24:$C$26,2,FALSE),0)+IFERROR(VLOOKUP(J27,기준!$B$29:$C$32,2,FALSE),0)+IFERROR(VLOOKUP(K27,기준!$B$35:$C$41,2,FALSE),0) | U27: =IFERROR(VLOOKUP(G27,기준!$B$10:$C$13,2,FALSE),0)+IFERROR(VLOOKUP(H27,기준!$B$16:$C$21,2,FALSE),0) | V27: =IFERROR(VLOOKUP(L27,기준!$B$44:$C$46,2,FALSE),0)+IFERROR(VLOOKUP(M27,기준!$B$49:$C$52,2,FALSE),0)+IFERROR(VLOOKUP(N27,기준!$B$55:$C$58,2,FALSE),0) | W27: =SUM(S27:V27) | X27: =MIN(IF(O27="Y",20,100),IF(P27="Y",40,100),IF(Q27="Y",50,100),IF(R27="Y",40,100)) | Y27: =MIN(W27,X27) | Z27: =RANK(Y27,$Y$2:$Y$34,0) | AA27: 공개·검증 | AB27: 미정 | AC27: =(IF(ISNUMBER(D27),1,0)+IF(ISNUMBER(E27),1,0)+IF(AND(F27<>"미상",F27<>""),1,0)+IF(AND(G27<>"미상",G27<>""),1,0)+IF(AND(H27<>"미상",H27<>""),1,0)+IF(AND(I27<>"미상",I27<>""),1,0)+IF(AND(J27<>"미상",J27<>""),1,0)+IF(AND(K27<>"미상",K27<>""),1,0)+IF(AND(L27<>"미상",L27<>""),1,0)+IF(AND(M27<>"미상",M27<>""),1,0)+IF(AND(N27<>"미상",N27<>""),1,0))&"/11" | AD27: EPA+DHA 937/캡슐·순도~75%·AlaskaOmega·IFOS·병포장 (필라이즈)
A28: 27 | B28: 종근당 프로메가 알티지 듀얼 | C28: 사람용 | D28: 300 | F28: 명시 | G28: rTG | H28: 일반어 | I28: 미상 | J28: 미상 | K28: 캡슐 | L28: 미상 | M28: 미상 | N28: 명시 | O28: =IF(H28="식물성","Y","N") | P28: N | Q28: =IF(AND(J28="취약",I28<>"있음",OR(M28="없음",M28="미상")),"Y","N") | R28: Y | S28: =IF(NOT(ISNUMBER(D28)),0,IF(D28>=300,20,IF(D28>=200,15,IF(D28>=100,10,5))))+IF(NOT(ISNUMBER(E28)),0,IF(E28>=60,10,IF(E28>=40,6,3)))+IFERROR(VLOOKUP(F28,기준!$B$4:$C$7,2,FALSE),0) | T28: =IFERROR(VLOOKUP(I28,기준!$B$24:$C$26,2,FALSE),0)+IFERROR(VLOOKUP(J28,기준!$B$29:$C$32,2,FALSE),0)+IFERROR(VLOOKUP(K28,기준!$B$35:$C$41,2,FALSE),0) | U28: =IFERROR(VLOOKUP(G28,기준!$B$10:$C$13,2,FALSE),0)+IFERROR(VLOOKUP(H28,기준!$B$16:$C$21,2,FALSE),0) | V28: =IFERROR(VLOOKUP(L28,기준!$B$44:$C$46,2,FALSE),0)+IFERROR(VLOOKUP(M28,기준!$B$49:$C$52,2,FALSE),0)+IFERROR(VLOOKUP(N28,기준!$B$55:$C$58,2,FALSE),0) | W28: =SUM(S28:V28) | X28: =MIN(IF(O28="Y",20,100),IF(P28="Y",40,100),IF(Q28="Y",50,100),IF(R28="Y",40,100)) | Y28: =MIN(W28,X28) | Z28: =RANK(Y28,$Y$2:$Y$34,0) | AA28: 라벨만 | AB28: 미정 | AC28: =(IF(ISNUMBER(D28),1,0)+IF(ISNUMBER(E28),1,0)+IF(AND(F28<>"미상",F28<>""),1,0)+IF(AND(G28<>"미상",G28<>""),1,0)+IF(AND(H28<>"미상",H28<>""),1,0)+IF(AND(I28<>"미상",I28<>""),1,0)+IF(AND(J28<>"미상",J28<>""),1,0)+IF(AND(K28<>"미상",K28<>""),1,0)+IF(AND(L28<>"미상",L28<>""),1,0)+IF(AND(M28<>"미상",M28<>""),1,0)+IF(AND(N28<>"미상",N28<>""),1,0))&"/11" | AD28: 1캡슐 EPA+DHA 300mg·rTG·AlaskaOmega(알래스카 명태유=일반어)·비타민A 첨가(눈건강 기능성)·식약처 이중기능성 (ckdhcmall/필라이즈)
A29: 28 | B29: 트루엔 알티지 오메가3 | C29: 사람용 | F29: 미상 | G29: rTG | H29: 일반어 | I29: 미상 | J29: 우수 | K29: 캡슐 | L29: 미상 | M29: 미상 | N29: 미상 | O29: =IF(H29="식물성","Y","N") | P29: N | Q29: =IF(AND(J29="취약",I29<>"있음",OR(M29="없음",M29="미상")),"Y","N") | R29: Y | S29: =IF(NOT(ISNUMBER(D29)),0,IF(D29>=300,20,IF(D29>=200,15,IF(D29>=100,10,5))))+IF(NOT(ISNUMBER(E29)),0,IF(E29>=60,10,IF(E29>=40,6,3)))+IFERROR(VLOOKUP(F29,기준!$B$4:$C$7,2,FALSE),0) | T29: =IFERROR(VLOOKUP(I29,기준!$B$24:$C$26,2,FALSE),0)+IFERROR(VLOOKUP(J29,기준!$B$29:$C$32,2,FALSE),0)+IFERROR(VLOOKUP(K29,기준!$B$35:$C$41,2,FALSE),0) | U29: =IFERROR(VLOOKUP(G29,기준!$B$10:$C$13,2,FALSE),0)+IFERROR(VLOOKUP(H29,기준!$B$16:$C$21,2,FALSE),0) | V29: =IFERROR(VLOOKUP(L29,기준!$B$44:$C$46,2,FALSE),0)+IFERROR(VLOOKUP(M29,기준!$B$49:$C$52,2,FALSE),0)+IFERROR(VLOOKUP(N29,기준!$B$55:$C$58,2,FALSE),0) | W29: =SUM(S29:V29) | X29: =MIN(IF(O29="Y",20,100),IF(P29="Y",40,100),IF(Q29="Y",50,100),IF(R29="Y",40,100)) | Y29: =MIN(W29,X29) | Z29: =RANK(Y29,$Y$2:$Y$34,0) | AA29: 라벨만 | AB29: 미정 | AC29: =(IF(ISNUMBER(D29),1,0)+IF(ISNUMBER(E29),1,0)+IF(AND(F29<>"미상",F29<>""),1,0)+IF(AND(G29<>"미상",G29<>""),1,0)+IF(AND(H29<>"미상",H29<>""),1,0)+IF(AND(I29<>"미상",I29<>""),1,0)+IF(AND(J29<>"미상",J29<>""),1,0)+IF(AND(K29<>"미상",K29<>""),1,0)+IF(AND(L29<>"미상",L29<>""),1,0)+IF(AND(M29<>"미상",M29<>""),1,0)+IF(AND(N29<>"미상",N29<>""),1,0))&"/11" | AD29: rTG·Pollack(명태/대구속 어체유=간유아님→대구상한X·일반어)·PVDC개별포장(우수)·비타민D3·per캡슐 EPA+DHA mg 미상 (dawnfactory 블로그·라벨확인필요)
A30: 29 | B30: 닥터닥터스 알티지 rTG 1200 | C30: 사람용 | D30: 1200 | F30: 명시 | G30: rTG | H30: 소형어 | I30: 미상 | J30: 미상 | K30: 캡슐 | L30: 있음 | M30: 미상 | N30: 미상 | O30: =IF(H30="식물성","Y","N") | P30: N | Q30: =IF(AND(J30="취약",I30<>"있음",OR(M30="없음",M30="미상")),"Y","N") | R30: Y | S30: =IF(NOT(ISNUMBER(D30)),0,IF(D30>=300,20,IF(D30>=200,15,IF(D30>=100,10,5))))+IF(NOT(ISNUMBER(E30)),0,IF(E30>=60,10,IF(E30>=40,6,3)))+IFERROR(VLOOKUP(F30,기준!$B$4:$C$7,2,FALSE),0) | T30: =IFERROR(VLOOKUP(I30,기준!$B$24:$C$26,2,FALSE),0)+IFERROR(VLOOKUP(J30,기준!$B$29:$C$32,2,FALSE),0)+IFERROR(VLOOKUP(K30,기준!$B$35:$C$41,2,FALSE),0) | U30: =IFERROR(VLOOKUP(G30,기준!$B$10:$C$13,2,FALSE),0)+IFERROR(VLOOKUP(H30,기준!$B$16:$C$21,2,FALSE),0) | V30: =IFERROR(VLOOKUP(L30,기준!$B$44:$C$46,2,FALSE),0)+IFERROR(VLOOKUP(M30,기준!$B$49:$C$52,2,FALSE),0)+IFERROR(VLOOKUP(N30,기준!$B$55:$C$58,2,FALSE),0) | W30: =SUM(S30:V30) | X30: =MIN(IF(O30="Y",20,100),IF(P30="Y",40,100),IF(Q30="Y",50,100),IF(R30="Y",40,100)) | Y30: =MIN(W30,X30) | Z30: =RANK(Y30,$Y$2:$Y$34,0) | AA30: 라벨만 | AB30: 미정 | AC30: =(IF(ISNUMBER(D30),1,0)+IF(ISNUMBER(E30),1,0)+IF(AND(F30<>"미상",F30<>""),1,0)+IF(AND(G30<>"미상",G30<>""),1,0)+IF(AND(H30<>"미상",H30<>""),1,0)+IF(AND(I30<>"미상",I30<>""),1,0)+IF(AND(J30<>"미상",J30<>""),1,0)+IF(AND(K30<>"미상",K30<>""),1,0)+IF(AND(L30<>"미상",L30<>""),1,0)+IF(AND(M30<>"미상",M30<>""),1,0)+IF(AND(N30<>"미상",N30<>""),1,0))&"/11" | AD30: 1캡슐 EPA800+DHA400=1200mg·100%멸치어유(소형어)·rTG·IFOS5STAR·비타민D 1000IU·90캡슐(3개월) (drdoctors.co.kr/11번가/필라이즈)
A31: 30 | B31: 위타민 알티지 | C31: 사람용 | D31: 980 | F31: 미상 | G31: rTG | H31: 미상 | I31: 미상 | J31: 미상 | K31: 캡슐 | L31: 있음 | M31: 일부 | N31: 명시 | O31: =IF(H31="식물성","Y","N") | P31: N | Q31: =IF(AND(J31="취약",I31<>"있음",OR(M31="없음",M31="미상")),"Y","N") | R31: N | S31: =IF(NOT(ISNUMBER(D31)),0,IF(D31>=300,20,IF(D31>=200,15,IF(D31>=100,10,5))))+IF(NOT(ISNUMBER(E31)),0,IF(E31>=60,10,IF(E31>=40,6,3)))+IFERROR(VLOOKUP(F31,기준!$B$4:$C$7,2,FALSE),0) | T31: =IFERROR(VLOOKUP(I31,기준!$B$24:$C$26,2,FALSE),0)+IFERROR(VLOOKUP(J31,기준!$B$29:$C$32,2,FALSE),0)+IFERROR(VLOOKUP(K31,기준!$B$35:$C$41,2,FALSE),0) | U31: =IFERROR(VLOOKUP(G31,기준!$B$10:$C$13,2,FALSE),0)+IFERROR(VLOOKUP(H31,기준!$B$16:$C$21,2,FALSE),0) | V31: =IFERROR(VLOOKUP(L31,기준!$B$44:$C$46,2,FALSE),0)+IFERROR(VLOOKUP(M31,기준!$B$49:$C$52,2,FALSE),0)+IFERROR(VLOOKUP(N31,기준!$B$55:$C$58,2,FALSE),0) | W31: =SUM(S31:V31) | X31: =MIN(IF(O31="Y",20,100),IF(P31="Y",40,100),IF(Q31="Y",50,100),IF(R31="Y",40,100)) | Y31: =MIN(W31,X31) | Z31: =RANK(Y31,$Y$2:$Y$34,0) | AA31: 공개·검증 | AB31: 미정 | AC31: =(IF(ISNUMBER(D31),1,0)+IF(ISNUMBER(E31),1,0)+IF(AND(F31<>"미상",F31<>""),1,0)+IF(AND(G31<>"미상",G31<>""),1,0)+IF(AND(H31<>"미상",H31<>""),1,0)+IF(AND(I31<>"미상",I31<>""),1,0)+IF(AND(J31<>"미상",J31<>""),1,0)+IF(AND(K31<>"미상",K31<>""),1,0)+IF(AND(L31<>"미상",L31<>""),1,0)+IF(AND(M31<>"미상",M31<>""),1,0)+IF(AND(N31<>"미상",N31<>""),1,0))&"/11" | AD31: 완제품 IFOS·EPA+DHA 980mg·rTG·KD파마 원료(원료+완제품IFOS5★)·별도SKU 1280mg 존재 (weetamin.co.kr)
A32: 31 | B32: 캘리포니아골드 뉴트리션 오메가3 | C32: 사람용 | D32: 300 | E32: 60 | F32: 명시 | G32: TG | H32: 소형어 | I32: 있음 | J32: 취약 | K32: 소프트젤 | L32: 미상 | M32: 일부 | N32: 미상 | O32: =IF(H32="식물성","Y","N") | P32: N | Q32: =IF(AND(J32="취약",I32<>"있음",OR(M32="없음",M32="미상")),"Y","N") | R32: N | S32: =IF(NOT(ISNUMBER(D32)),0,IF(D32>=300,20,IF(D32>=200,15,IF(D32>=100,10,5))))+IF(NOT(ISNUMBER(E32)),0,IF(E32>=60,10,IF(E32>=40,6,3)))+IFERROR(VLOOKUP(F32,기준!$B$4:$C$7,2,FALSE),0) | T32: =IFERROR(VLOOKUP(I32,기준!$B$24:$C$26,2,FALSE),0)+IFERROR(VLOOKUP(J32,기준!$B$29:$C$32,2,FALSE),0)+IFERROR(VLOOKUP(K32,기준!$B$35:$C$41,2,FALSE),0) | U32: =IFERROR(VLOOKUP(G32,기준!$B$10:$C$13,2,FALSE),0)+IFERROR(VLOOKUP(H32,기준!$B$16:$C$21,2,FALSE),0) | V32: =IFERROR(VLOOKUP(L32,기준!$B$44:$C$46,2,FALSE),0)+IFERROR(VLOOKUP(M32,기준!$B$49:$C$52,2,FALSE),0)+IFERROR(VLOOKUP(N32,기준!$B$55:$C$58,2,FALSE),0) | W32: =SUM(S32:V32) | X32: =MIN(IF(O32="Y",20,100),IF(P32="Y",40,100),IF(Q32="Y",50,100),IF(R32="Y",40,100)) | Y32: =MIN(W32,X32) | Z32: =RANK(Y32,$Y$2:$Y$34,0) | AA32: 공개·검증 | AB32: 미정 | AC32: =(IF(ISNUMBER(D32),1,0)+IF(ISNUMBER(E32),1,0)+IF(AND(F32<>"미상",F32<>""),1,0)+IF(AND(G32<>"미상",G32<>""),1,0)+IF(AND(H32<>"미상",H32<>""),1,0)+IF(AND(I32<>"미상",I32<>""),1,0)+IF(AND(J32<>"미상",J32<>""),1,0)+IF(AND(K32<>"미상",K32<>""),1,0)+IF(AND(L32<>"미상",L32<>""),1,0)+IF(AND(M32<>"미상",M32<>""),1,0)+IF(AND(N32<>"미상",N32<>""),1,0))&"/11" | AD32: 1캡슐 EPA180+DHA120=300mg(총500mg·순도60%)·멸치/고등어/정어리/참치·농축TG·비타민E·중금속/PCB시험 (iHerb)
A33: 32 | B33: 담백하루 초임계 알티지 1000 | C33: 사람용 | D33: 1000 | E33: 79.7 | F33: 미상 | G33: rTG | H33: 미상 | I33: 미상 | J33: 미상 | K33: 캡슐 | L33: 있음 | M33: 일부 | N33: 명시 | O33: =IF(H33="식물성","Y","N") | P33: N | Q33: =IF(AND(J33="취약",I33<>"있음",OR(M33="없음",M33="미상")),"Y","N") | R33: Y | S33: =IF(NOT(ISNUMBER(D33)),0,IF(D33>=300,20,IF(D33>=200,15,IF(D33>=100,10,5))))+IF(NOT(ISNUMBER(E33)),0,IF(E33>=60,10,IF(E33>=40,6,3)))+IFERROR(VLOOKUP(F33,기준!$B$4:$C$7,2,FALSE),0) | T33: =IFERROR(VLOOKUP(I33,기준!$B$24:$C$26,2,FALSE),0)+IFERROR(VLOOKUP(J33,기준!$B$29:$C$32,2,FALSE),0)+IFERROR(VLOOKUP(K33,기준!$B$35:$C$41,2,FALSE),0) | U33: =IFERROR(VLOOKUP(G33,기준!$B$10:$C$13,2,FALSE),0)+IFERROR(VLOOKUP(H33,기준!$B$16:$C$21,2,FALSE),0) | V33: =IFERROR(VLOOKUP(L33,기준!$B$44:$C$46,2,FALSE),0)+IFERROR(VLOOKUP(M33,기준!$B$49:$C$52,2,FALSE),0)+IFERROR(VLOOKUP(N33,기준!$B$55:$C$58,2,FALSE),0) | W33: =SUM(S33:V33) | X33: =MIN(IF(O33="Y",20,100),IF(P33="Y",40,100),IF(Q33="Y",50,100),IF(R33="Y",40,100)) | Y33: =MIN(W33,X33) | Z33: =RANK(Y33,$Y$2:$Y$34,0) | AA33: 공개·검증 | AB33: 미정 | AC33: =(IF(ISNUMBER(D33),1,0)+IF(ISNUMBER(E33),1,0)+IF(AND(F33<>"미상",F33<>""),1,0)+IF(AND(G33<>"미상",G33<>""),1,0)+IF(AND(H33<>"미상",H33<>""),1,0)+IF(AND(I33<>"미상",I33<>""),1,0)+IF(AND(J33<>"미상",J33<>""),1,0)+IF(AND(K33<>"미상",K33<>""),1,0)+IF(AND(L33<>"미상",L33<>""),1,0)+IF(AND(M33<>"미상",M33<>""),1,0)+IF(AND(N33<>"미상",N33<>""),1,0))&"/11" | AD33: EPA+DHA 1000mg/1255mg캡슐(순도79.7%)·KD파마 원료·초임계rTG·완제품IFOS·비타민D 15μg·AlpiBio제조 (dambaekharu/danawa/필라이즈)
A34: 33 | B34: 고려은단 식물성 퓨어 알티지 | C34: 사람용·식물성 | E34: 75 | F34: 미상 | G34: rTG | H34: 조류 | I34: 미상 | J34: 미상 | K34: 캡슐 | L34: 미상 | M34: 미상 | N34: 명시 | O34: =IF(H34="식물성","Y","N") | P34: N | Q34: =IF(AND(J34="취약",I34<>"있음",OR(M34="없음",M34="미상")),"Y","N") | R34: N | S34: =IF(NOT(ISNUMBER(D34)),0,IF(D34>=300,20,IF(D34>=200,15,IF(D34>=100,10,5))))+IF(NOT(ISNUMBER(E34)),0,IF(E34>=60,10,IF(E34>=40,6,3)))+IFERROR(VLOOKUP(F34,기준!$B$4:$C$7,2,FALSE),0) | T34: =IFERROR(VLOOKUP(I34,기준!$B$24:$C$26,2,FALSE),0)+IFERROR(VLOOKUP(J34,기준!$B$29:$C$32,2,FALSE),0)+IFERROR(VLOOKUP(K34,기준!$B$35:$C$41,2,FALSE),0) | U34: =IFERROR(VLOOKUP(G34,기준!$B$10:$C$13,2,FALSE),0)+IFERROR(VLOOKUP(H34,기준!$B$16:$C$21,2,FALSE),0) | V34: =IFERROR(VLOOKUP(L34,기준!$B$44:$C$46,2,FALSE),0)+IFERROR(VLOOKUP(M34,기준!$B$49:$C$52,2,FALSE),0)+IFERROR(VLOOKUP(N34,기준!$B$55:$C$58,2,FALSE),0) | W34: =SUM(S34:V34) | X34: =MIN(IF(O34="Y",20,100),IF(P34="Y",40,100),IF(Q34="Y",50,100),IF(R34="Y",40,100)) | Y34: =MIN(W34,X34) | Z34: =RANK(Y34,$Y$2:$Y$34,0) | AA34: 라벨만 | AB34: DHA중심(조류) | AC34: =(IF(ISNUMBER(D34),1,0)+IF(ISNUMBER(E34),1,0)+IF(AND(F34<>"미상",F34<>""),1,0)+IF(AND(G34<>"미상",G34<>""),1,0)+IF(AND(H34<>"미상",H34<>""),1,0)+IF(AND(I34<>"미상",I34<>""),1,0)+IF(AND(J34<>"미상",J34<>""),1,0)+IF(AND(K34<>"미상",K34<>""),1,0)+IF(AND(L34<>"미상",L34<>""),1,0)+IF(AND(M34<>"미상",M34<>""),1,0)+IF(AND(N34<>"미상",N34<>""),1,0))&"/11" | AD34: 무균배양 미세조류(DSM 원료·순도75%)·rTG·EPA/DHA 균형·상한 부적용·per캡슐mg SKU별 상이(기억력+ 900mg) (고려은단/메디파나/소셜타임스)
